Workbook
Name n: [1]인문!#REF!
Name n: [1]인문!#REF!
Name n: [1]인문!#REF!
Name n: [1]인문!#REF!
Name n: [1]인문!#REF!
Name n: [1]인문!#REF!
Name n: [1]인문!#REF!
Name n: [1]인문!#REF!
Name n: [1]인문!#REF!
Name n: [1]인문!#REF!
Name n: [2]인문!#REF!
Name n: [1]인문!#REF!

Sheet 3-6
A1: 수능모의 평가 3학년 06반
A2: 실시일 : 2014. 10. 7
A3: 번 호 | B3: 성 명 | C3: 언어 | D3: 등급 | E3: 표준점수 | F3: 수리 | G3: 등급 | H3: 표준점수 | I3: 외국어 | J3: 등급 | K3: 표준점수 | L3: 언수외 소 계 | M3: 언수외 표준소계 | N3: 언수외석 차 | O3: 탐구영역 | Q3: 탐구소계 | R3: 총점 | S3: 반석차 | U3: 누계표
A4: 1 | B4: 강동호 | C4: 79 | D4: =LOOKUP(C4,#REF!,#REF!) -> #REF! | E4: =((C4-#REF!)/#REF!)*20+100 -> #REF! | F4: 33 | G4: =LOOKUP(F4,#REF!,#REF!) -> #REF! | H4: =((F4-#REF!)/#REF!)*20+100 -> #REF! | I4: 65 | J4: =LOOKUP(I4,#REF!,#REF!) -> #REF! | K4: =((I4-#REF!)/#REF!)*20+100 -> #REF! | L4: =SUM(C4,F4,I4) -> 177 | M4: =SUM(E4,H4,K4) -> #REF! | N4: =RANK(L4,$L$4:$L$39) -> 24 | O4: 11 | P4: 9 | Q4: =(SUM(O4:P4)) -> 20 | R4: =SUM(L4,Q4) -> 197 | S4: =RANK(R4,$R$4:$R$39) -> 25 | U4: 400 | W4: 399
A5: 2 | B5: 강세훈 | C5: 96 | D5: =LOOKUP(C5,#REF!,#REF!) -> #REF! | E5: =((C5-#REF!)/#REF!)*20+100 -> #REF! | F5: 51 | G5: =LOOKUP(F5,#REF!,#REF!) -> #REF! | H5: =((F5-#REF!)/#REF!)*20+100 -> #REF! | I5: 83 | J5: =LOOKUP(I5,#REF!,#REF!) -> #REF! | K5: =((I5-#REF!)/#REF!)*20+100 -> #REF! | L5: =SUM(C5,F5,I5) -> 230 | M5: =SUM(E5,H5,K5) -> #REF! | N5: =RANK(L5,$L$4:$L$39) -> 9 | O5: 21 | P5: 20 | Q5: =(SUM(O5:P5)) -> 41 | R5: =SUM(L5,Q5) -> 271 | S5: =RANK(R5,$R$4:$R$39) -> 15 | U5: 390 | V5: =FREQUENCY($R$4:$R$39,W4:W24) -> 0 | W5: 389
A6: 3 | B6: 강전희 | C6: 34 | D6: =LOOKUP(C6,#REF!,#REF!) -> #REF! | E6: =((C6-#REF!)/#REF!)*20+100 -> #REF! | F6: 21 | G6: =LOOKUP(F6,#REF!,#REF!) -> #REF! | H6: =((F6-#REF!)/#REF!)*20+100 -> #REF! | I6: 43 | J6: =LOOKUP(I6,#REF!,#REF!) -> #REF! | K6: =((I6-#REF!)/#REF!)*20+100 -> #REF! | L6: =SUM(C6,F6,I6) -> 98 | M6: =SUM(E6,H6,K6) -> #REF! | N6: =RANK(L6,$L$4:$L$39) -> 33 | O6: 5 | P6: 27 | Q6: =(SUM(O6:P6)) -> 32 | R6: =SUM(L6,Q6) -> 130 | S6: =RANK(R6,$R$4:$R$39) -> 34 | U6: 380 | V6: =FREQUENCY($R$4:$R$39,W5:W25) -> 0 | W6: 379
A7: 4 | B7: 김도영 | C7: 80 | D7: =LOOKUP(C7,#REF!,#REF!) -> #REF! | E7: =((C7-#REF!)/#REF!)*20+100 -> #REF! | F7: 38 | G7: =LOOKUP(F7,#REF!,#REF!) -> #REF! | H7: =((F7-#REF!)/#REF!)*20+100 -> #REF! | I7: 82 | J7: =LOOKUP(I7,#REF!,#REF!) -> #REF! | K7: =((I7-#REF!)/#REF!)*20+100 -> #REF! | L7: =SUM(C7,F7,I7) -> 200 | M7: =SUM(E7,H7,K7) -> #REF! | N7: =RANK(L7,$L$4:$L$39) -> 16 | O7: 39 | P7: 22 | Q7: =(SUM(O7:P7)) -> 61 | R7: =SUM(L7,Q7) -> 261 | S7: =RANK(R7,$R$4:$R$39) -> 18 | U7: 370 | V7: =FREQUENCY($R$4:$R$39,W6:W26) -> 1 | W7: 369
A8: 5 | B8: 김석우 | C8: 49 | D8: =LOOKUP(C8,#REF!,#REF!) -> #REF! | E8: =((C8-#REF!)/#REF!)*20+100 -> #REF! | F8: 26 | G8: =LOOKUP(F8,#REF!,#REF!) -> #REF! | H8: =((F8-#REF!)/#REF!)*20+100 -> #REF! | I8: 79 | J8: =LOOKUP(I8,#REF!,#REF!) -> #REF! | K8: =((I8-#REF!)/#REF!)*20+100 -> #REF! | L8: =SUM(C8,F8,I8) -> 154 | M8: =SUM(E8,H8,K8) -> #REF! | N8: =RANK(L8,$L$4:$L$39) -> 27 | O8: 20 | P8: 10 | Q8: =(SUM(O8:P8)) -> 30 | R8: =SUM(L8,Q8) -> 184 | S8: =RANK(R8,$R$4:$R$39) -> 27 | U8: 360 | V8: =FREQUENCY($R$4:$R$39,W7:W27) -> 2 | W8: 359
A9: 6 | B9: 김용현 | C9: 96 | D9: =LOOKUP(C9,#REF!,#REF!) -> #REF! | E9: =((C9-#REF!)/#REF!)*20+100 -> #REF! | F9: 39 | G9: =LOOKUP(F9,#REF!,#REF!) -> #REF! | H9: =((F9-#REF!)/#REF!)*20+100 -> #REF! | I9: 72 | J9: =LOOKUP(I9,#REF!,#REF!) -> #REF! | K9: =((I9-#REF!)/#REF!)*20+100 -> #REF! | L9: =SUM(C9,F9,I9) -> 207 | M9: =SUM(E9,H9,K9) -> #REF! | N9: =RANK(L9,$L$4:$L$39) -> 14 | O9: 35 | P9: 31 | Q9: =(SUM(O9:P9)) -> 66 | R9: =SUM(L9,Q9) -> 273 | S9: =RANK(R9,$R$4:$R$39) -> 14 | U9: 350 | V9: =FREQUENCY($R$4:$R$39,W8:W28) -> 1 | W9: 349
A10: 7 | B10: 김원탁 | C10: 85 | D10: =LOOKUP(C10,#REF!,#REF!) -> #REF! | E10: =((C10-#REF!)/#REF!)*20+100 -> #REF! | F10: 44 | G10: =LOOKUP(F10,#REF!,#REF!) -> #REF! | H10: =((F10-#REF!)/#REF!)*20+100 -> #REF! | I10: 72 | J10: =LOOKUP(I10,#REF!,#REF!) -> #REF! | K10: =((I10-#REF!)/#REF!)*20+100 -> #REF! | L10: =SUM(C10,F10,I10) -> 201 | M10: =SUM(E10,H10,K10) -> #REF! | N10: =RANK(L10,$L$4:$L$39) -> 15 | O10: 33 | P10: 34 | Q10: =(SUM(O10:P10)) -> 67 | R10: =SUM(L10,Q10) -> 268 | S10: =RANK(R10,$R$4:$R$39) -> 16 | U10: 340 | V10: =FREQUENCY($R$4:$R$39,W9:W29) -> 0 | W10: 339
A11: 8 | B11: 김재우 | C11: 92 | D11: =LOOKUP(C11,#REF!,#REF!) -> #REF! | E11: =((C11-#REF!)/#REF!)*20+100 -> #REF! | F11: 20 | G11: =LOOKUP(F11,#REF!,#REF!) -> #REF! | H11: =((F11-#REF!)/#REF!)*20+100 -> #REF! | I11: 63 | J11: =LOOKUP(I11,#REF!,#REF!) -> #REF! | K11: =((I11-#REF!)/#REF!)*20+100 -> #REF! | L11: =SUM(C11,F11,I11) -> 175 | M11: =SUM(E11,H11,K11) -> #REF! | N11: =RANK(L11,$L$4:$L$39) -> 25 | O11: 8 | P11: 18 | Q11: =(SUM(O11:P11)) -> 26 | R11: =SUM(L11,Q11) -> 201 | S11: =RANK(R11,$R$4:$R$39) -> 24 | U11: 330 | V11: =FREQUENCY($R$4:$R$39,W10:W30) -> 1 | W11: 329
A12: 9 | B12: 김종헌 | C12: 85 | D12: =LOOKUP(C12,#REF!,#REF!) -> #REF! | E12: =((C12-#REF!)/#REF!)*20+100 -> #REF! | F12: 28 | G12: =LOOKUP(F12,#REF!,#REF!) -> #REF! | H12: =((F12-#REF!)/#REF!)*20+100 -> #REF! | I12: 69 | J12: =LOOKUP(I12,#REF!,#REF!) -> #REF! | K12: =((I12-#REF!)/#REF!)*20+100 -> #REF! | L12: =SUM(C12,F12,I12) -> 182 | M12: =SUM(E12,H12,K12) -> #REF! | N12: =RANK(L12,$L$4:$L$39) -> 23 | O12: 34 | P12: 29 | Q12: =(SUM(O12:P12)) -> 63 | R12: =SUM(L12,Q12) -> 245 | S12: =RANK(R12,$R$4:$R$39) -> 19 | U12: 320 | V12: =FREQUENCY($R$4:$R$39,W11:W31) -> 0 | W12: 319
A13: 10 | B13: 김지찬 | C13: 52 | D13: =LOOKUP(C13,#REF!,#REF!) -> #REF! | E13: =((C13-#REF!)/#REF!)*20+100 -> #REF! | F13: 3 | G13: =LOOKUP(F13,#REF!,#REF!) -> #REF! | H13: =((F13-#REF!)/#REF!)*20+100 -> #REF! | I13: 28 | J13: =LOOKUP(I13,#REF!,#REF!) -> #REF! | K13: =((I13-#REF!)/#REF!)*20+100 -> #REF! | L13: =SUM(C13,F13,I13) -> 83 | M13: =SUM(E13,H13,K13) -> #REF! | N13: =RANK(L13,$L$4:$L$39) -> 36 | O13: 17 | P13: 15 | Q13: =(SUM(O13:P13)) -> 32 | R13: =SUM(L13,Q13) -> 115 | S13: =RANK(R13,$R$4:$R$39) -> 36 | U13: 310 | V13: =FREQUENCY($R$4:$R$39,W12:W32) -> 0 | W13: 309
A14: 11 | B14: 노현우 | C14: 98 | D14: =LOOKUP(C14,예상등급!$A$5:$A$13,예상등급!$B$5:$B$13) -> 1 | E14: =((C14-예상등급!#REF!)/예상등급!#REF!)*20+100 -> #REF! | F14: 88 | G14: =LOOKUP(F14,예상등급!$D$19:$D$27,예상등급!$E$19:$E$27) -> 1 | H14: =((F14-예상등급!#REF!)/예상등급!#REF!)*20+100 -> #REF! | I14: 92 | J14: =LOOKUP(I14,#REF!,#REF!) -> #REF! | K14: =((I14-#REF!)/#REF!)*20+100 -> #REF! | L14: =SUM(C14,F14,I14) -> 278 | M14: =SUM(E14,H14,K14) -> #REF! | N14: =RANK(L14,$L$4:$L$39) -> 2 | O14: 47 | P14: 45 | Q14: =(SUM(O14:P14)) -> 92 | R14: =SUM(L14,Q14) -> 370 | S14: =RANK(R14,$R$4:$R$39) -> 1 | U14: 300 | V14: =FREQUENCY($R$4:$R$39,W13:W33) -> 2 | W14: 299
A15: 12 | B15: 박상준 | C15: 76 | D15: =LOOKUP(C15,#REF!,#REF!) -> #REF! | E15: =((C15-#REF!)/#REF!)*20+100 -> #REF! | F15: 48 | G15: =LOOKUP(F15,예상등급!$D$19:$D$27,예상등급!$E$19:$E$27) -> 1 | H15: =((F15-예상등급!#REF!)/예상등급!#REF!)*20+100 -> #REF! | I15: 73 | J15: =LOOKUP(I15,#REF!,#REF!) -> #REF! | K15: =((I15-#REF!)/#REF!)*20+100 -> #REF! | L15: =SUM(C15,F15,I15) -> 197 | M15: =SUM(E15,H15,K15) -> #REF! | N15: =RANK(L15,$L$4:$L$39) -> 19 | O15: 27 | P15: 38 | Q15: =(SUM(O15:P15)) -> 65 | R15: =SUM(L15,Q15) -> 262 | S15: =RANK(R15,$R$4:$R$39) -> 17 | U15: 290 | V15: =FREQUENCY($R$4:$R$39,W14:W34) -> 2 | W15: 289
A16: 13 | B16: 박성민 | C16: 98 | D16: =LOOKUP(C16,#REF!,#REF!) -> #REF! | E16: =((C16-#REF!)/#REF!)*20+100 -> #REF! | F16: 62 | G16: =LOOKUP(F16,#REF!,#REF!) -> #REF! | H16: =((F16-#REF!)/#REF!)*20+100 -> #REF! | I16: 66 | J16: =LOOKUP(I16,#REF!,#REF!) -> #REF! | K16: =((I16-#REF!)/#REF!)*20+100 -> #REF! | L16: =SUM(C16,F16,I16) -> 226 | M16: =SUM(E16,H16,K16) -> #REF! | N16: =RANK(L16,$L$4:$L$39) -> 11 | O16: 29 | P16: 33 | Q16: =(SUM(O16:P16)) -> 62 | R16: =SUM(L16,Q16) -> 288 | S16: =RANK(R16,$R$4:$R$39) -> 10 | U16: 280 | V16: =FREQUENCY($R$4:$R$39,W15:W35) -> 1 | W16: 279
A17: 14 | B17: 박지우 | C17: 100 | D17: =LOOKUP(C17,#REF!,#REF!) -> #REF! | E17: =((C17-#REF!)/#REF!)*20+100 -> #REF! | F17: 65 | G17: =LOOKUP(F17,#REF!,#REF!) -> #REF! | H17: =((F17-#REF!)/#REF!)*20+100 -> #REF! | I17: 92 | J17: =LOOKUP(I17,#REF!,#REF!) -> #REF! | K17: =((I17-#REF!)/#REF!)*20+100 -> #REF! | L17: =SUM(C17,F17,I17) -> 257 | M17: =SUM(E17,H17,K17) -> #REF! | N17: =RANK(L17,$L$4:$L$39) -> 5 | O17: 40 | P17: 37 | Q17: =(SUM(O17:P17)) -> 77 | R17: =SUM(L17,Q17) -> 334 | S17: =RANK(R17,$R$4:$R$39) -> 5 | U17: 270 | V17: =FREQUENCY($R$4:$R$39,W16:W36) -> 5 | W17: 269
A18: 15 | B18: 방인서 | C18: 91 | D18: =LOOKUP(C18,#REF!,#REF!) -> #REF! | E18: =((C18-#REF!)/#REF!)*20+100 -> #REF! | F18: 42 | G18: =LOOKUP(F18,#REF!,#REF!) -> #REF! | H18: =((F18-#REF!)/#REF!)*20+100 -> #REF! | I18: 66 | J18: =LOOKUP(I18,#REF!,#REF!) -> #REF! | K18: =((I18-#REF!)/#REF!)*20+100 -> #REF! | L18: =SUM(C18,F18,I18) -> 199 | M18: =SUM(E18,H18,K18) -> #REF! | N18: =RANK(L18,$L$4:$L$39) -> 17 | O18: 18 | P18: 28 | Q18: =(SUM(O18:P18)) -> 46 | R18: =SUM(L18,Q18) -> 245 | S18: =RANK(R18,$R$4:$R$39) -> 19 | U18: 260 | V18: =FREQUENCY($R$4:$R$39,W17:W37) -> 3 | W18: 259
A19: 16 | B19: 소현수 | C19: 86 | D19: =LOOKUP(C19,#REF!,#REF!) -> #REF! | E19: =((C19-#REF!)/#REF!)*20+100 -> #REF! | F19: 60 | G19: =LOOKUP(F19,#REF!,#REF!) -> #REF! | H19: =((F19-#REF!)/#REF!)*20+100 -> #REF! | I19: 51 | J19: =LOOKUP(I19,#REF!,#REF!) -> #REF! | K19: =((I19-#REF!)/#REF!)*20+100 -> #REF! | L19: =SUM(C19,F19,I19) -> 197 | M19: =SUM(E19,H19,K19) -> #REF! | N19: =RANK(L19,$L$4:$L$39) -> 19 | O19: 43 | P19: 38 | Q19: =(SUM(O19:P19)) -> 81 | R19: =SUM(L19,Q19) -> 278 | S19: =RANK(R19,$R$4:$R$39) -> 11 | U19: 250 | V19: =FREQUENCY($R$4:$R$39,W18:W39) -> 0 | W19: 249
A20: 17 | B20: 신재범 | C20: 52 | D20: =LOOKUP(C20,#REF!,#REF!) -> #REF! | E20: =((C20-#REF!)/#REF!)*20+100 -> #REF! | F20: 12 | G20: =LOOKUP(F20,#REF!,#REF!) -> #REF! | H20: =((F20-#REF!)/#REF!)*20+100 -> #REF! | I20: 45 | J20: =LOOKUP(I20,#REF!,#REF!) -> #REF! | K20: =((I20-#REF!)/#REF!)*20+100 -> #REF! | L20: =SUM(C20,F20,I20) -> 109 | M20: =SUM(E20,H20,K20) -> #REF! | N20: =RANK(L20,$L$4:$L$39) -> 32 | O20: 20 | P20: 26 | Q20: =(SUM(O20:P20)) -> 46 | R20: =SUM(L20,Q20) -> 155 | S20: =RANK(R20,$R$4:$R$39) -> 31 | U20: 240 | V20: =FREQUENCY($R$4:$R$39,W19:W39) -> 2 | W20: 239
A21: 18 | B21: 양한솔 | C21: 70 | D21: =LOOKUP(C21,#REF!,#REF!) -> #REF! | E21: =((C21-#REF!)/#REF!)*20+100 -> #REF! | F21: 35 | G21: =LOOKUP(F21,#REF!,#REF!) -> #REF! | H21: =((F21-#REF!)/#REF!)*20+100 -> #REF! | I21: 37 | J21: =LOOKUP(I21,#REF!,#REF!) -> #REF! | K21: =((I21-#REF!)/#REF!)*20+100 -> #REF! | L21: =SUM(C21,F21,I21) -> 142 | M21: =SUM(E21,H21,K21) -> #REF! | N21: =RANK(L21,$L$4:$L$39) -> 29 | O21: 12 | P21: 18 | Q21: =(SUM(O21:P21)) -> 30 | R21: =SUM(L21,Q21) -> 172 | S21: =RANK(R21,$R$4:$R$39) -> 29 | U21: 230 | V21: =FREQUENCY($R$4:$R$39,W20:W39) -> 2 | W21: 229
A22: 19 | B22: 유동주 | C22: 83 | D22: =LOOKUP(C22,#REF!,#REF!) -> #REF! | E22: =((C22-#REF!)/#REF!)*20+100 -> #REF! | F22: 27 | G22: =LOOKUP(F22,#REF!,#REF!) -> #REF! | H22: =((F22-#REF!)/#REF!)*20+100 -> #REF! | I22: 77 | J22: =LOOKUP(I22,#REF!,#REF!) -> #REF! | K22: =((I22-#REF!)/#REF!)*20+100 -> #REF! | L22: =SUM(C22,F22,I22) -> 187 | M22: =SUM(E22,H22,K22) -> #REF! | N22: =RANK(L22,$L$4:$L$39) -> 22 | O22: 13 | P22: 23 | Q22: =(SUM(O22:P22)) -> 36 | R22: =SUM(L22,Q22) -> 223 | S22: =RANK(R22,$R$4:$R$39) -> 23 | U22: 220 | V22: =FREQUENCY($R$4:$R$39,W21:W40) -> 1 | W22: 219
A23: 20 | B23: 유민종 | C23: 77 | D23: =LOOKUP(C23,#REF!,#REF!) -> #REF! | E23: =((C23-#REF!)/#REF!)*20+100 -> #REF! | F23: 31 | G23: =LOOKUP(F23,#REF!,#REF!) -> #REF! | H23: =((F23-#REF!)/#REF!)*20+100 -> #REF! | I23: 83 | J23: =LOOKUP(I23,#REF!,#REF!) -> #REF! | K23: =((I23-#REF!)/#REF!)*20+100 -> #REF! | L23: =SUM(C23,F23,I23) -> 191 | M23: =SUM(E23,H23,K23) -> #REF! | N23: =RANK(L23,$L$4:$L$39) -> 21 | O23: 23 | P23: 25 | Q23: =(SUM(O23:P23)) -> 48 | R23: =SUM(L23,Q23) -> 239 | S23: =RANK(R23,$R$4:$R$39) -> 21 | U23: 210 | V23: =FREQUENCY($R$4:$R$39,W22:W41) -> 0 | W23: 209
A24: 21 | B24: 유찬종 | C24: 38 | D24: =LOOKUP(C24,#REF!,#REF!) -> #REF! | E24: =((C24-#REF!)/#REF!)*20+100 -> #REF! | F24: 14 | G24: =LOOKUP(F24,#REF!,#REF!) -> #REF! | H24: =((F24-#REF!)/#REF!)*20+100 -> #REF! | I24: 41 | J24: =LOOKUP(I24,#REF!,#REF!) -> #REF! | K24: =((I24-#REF!)/#REF!)*20+100 -> #REF! | L24: =SUM(C24,F24,I24) -> 93 | M24: =SUM(E24,H24,K24) -> #REF! | N24: =RANK(L24,$L$4:$L$39) -> 34 | O24: 12 | P24: 17 | Q24: =(SUM(O24:P24)) -> 29 | R24: =SUM(L24,Q24) -> 122 | S24: =RANK(R24,$R$4:$R$39) -> 35 | U24: 200 | V24: =FREQUENCY($R$4:$R$39,W23:W42) -> 1 | W24: 199
A25: 22 | B25: 유태상 | C25: 87 | D25: =LOOKUP(C25,#REF!,#REF!) -> #REF! | E25: =((C25-#REF!)/#REF!)*20+100 -> #REF! | F25: 80 | G25: =LOOKUP(F25,#REF!,#REF!) -> #REF! | H25: =((F25-#REF!)/#REF!)*20+100 -> #REF! | I25: 75 | J25: =LOOKUP(I25,#REF!,#REF!) -> #REF! | K25: =((I25-#REF!)/#REF!)*20+100 -> #REF! | L25: =SUM(C25,F25,I25) -> 242 | M25: =SUM(E25,H25,K25) -> #REF! | N25: =RANK(L25,$L$4:$L$39) -> 8 | O25: 20 | P25: 38 | Q25: =(SUM(O25:P25)) -> 58 | R25: =SUM(L25,Q25) -> 300 | S25: =RANK(R25,$R$4:$R$39) -> 7 | U25: 190 | V25: =FREQUENCY($R$4:$R$39,W24:W43) -> 2 | W25: 189
A26: 23 | B26: 이대현 | C26: 90 | D26: =LOOKUP(C26,#REF!,#REF!) -> #REF! | E26: =((C26-#REF!)/#REF!)*20+100 -> #REF! | F26: 46 | G26: =LOOKUP(F26,#REF!,#REF!) -> #REF! | H26: =((F26-#REF!)/#REF!)*20+100 -> #REF! | I26: 87 | J26: =LOOKUP(I26,#REF!,#REF!) -> #REF! | K26: =((I26-#REF!)/#REF!)*20+100 -> #REF! | L26: =SUM(C26,F26,I26) -> 223 | M26: =SUM(E26,H26,K26) -> #REF! | N26: =RANK(L26,$L$4:$L$39) -> 12 | O26: 37 | P26: 15 | Q26: =(SUM(O26:P26)) -> 52 | R26: =SUM(L26,Q26) -> 275 | S26: =RANK(R26,$R$4:$R$39) -> 12 | U26: 190이하 | V26: =FREQUENCY($R$4:$R$39,W25:W44) -> 10
A27: 24 | B27: 이동근 | C27: 89 | D27: =LOOKUP(C27,#REF!,#REF!) -> #REF! | E27: =((C27-#REF!)/#REF!)*20+100 -> #REF! | F27: 55 | G27: =LOOKUP(F27,#REF!,#REF!) -> #REF! | H27: =((F27-#REF!)/#REF!)*20+100 -> #REF! | I27: 85 | J27: =LOOKUP(I27,#REF!,#REF!) -> #REF! | K27: =((I27-#REF!)/#REF!)*20+100 -> #REF! | L27: =SUM(C27,F27,I27) -> 229 | M27: =SUM(E27,H27,K27) -> #REF! | N27: =RANK(L27,$L$4:$L$39) -> 10 | O27: 25 | P27: 20 | Q27: =(SUM(O27:P27)) -> 45 | R27: =SUM(L27,Q27) -> 274 | S27: =RANK(R27,$R$4:$R$39) -> 13 | U27: 합계 | V27: =SUM(V4:V26) -> 36
A28: 25 | B28: 이승민 | C28: 96 | D28: =LOOKUP(C28,#REF!,#REF!) -> #REF! | E28: =((C28-#REF!)/#REF!)*20+100 -> #REF! | F28: 46 | G28: =LOOKUP(F28,#REF!,#REF!) -> #REF! | H28: =((F28-#REF!)/#REF!)*20+100 -> #REF! | I28: 70 | J28: =LOOKUP(I28,#REF!,#REF!) -> #REF! | K28: =((I28-#REF!)/#REF!)*20+100 -> #REF! | L28: =SUM(C28,F28,I28) -> 212 | M28: =SUM(E28,H28,K28) -> #REF! | N28: =RANK(L28,$L$4:$L$39) -> 13 | O28: 35 | P28: 45 | Q28: =(SUM(O28:P28)) -> 80 | R28: =SUM(L28,Q28) -> 292 | S28: =RANK(R28,$R$4:$R$39) -> 9
A29: 26 | B29: 이승현 | C29: 84 | D29: =LOOKUP(C29,예상등급!$A$5:$A$13,예상등급!$B$5:$B$13) -> 1 | E29: =((C29-예상등급!#REF!)/예상등급!#REF!)*20+100 -> #REF! | F29: 78 | G29: =LOOKUP(F29,예상등급!$D$19:$D$27,예상등급!$E$19:$E$27) -> 1 | H29: =((F29-예상등급!#REF!)/예상등급!#REF!)*20+100 -> #REF! | I29: 85 | J29: =LOOKUP(I29,#REF!,#REF!) -> #REF! | K29: =((I29-#REF!)/#REF!)*20+100 -> #REF! | L29: =SUM(C29,F29,I29) -> 247 | M29: =SUM(E29,H29,K29) -> #REF! | N29: =RANK(L29,$L$4:$L$39) -> 7 | O29: 30 | P29: 24 | Q29: =(SUM(O29:P29)) -> 54 | R29: =SUM(L29,Q29) -> 301 | S29: =RANK(R29,$R$4:$R$39) -> 6
A30: 27 | B30: 이준영 | C30: 97 | D30: =LOOKUP(C30,#REF!,#REF!) -> #REF! | E30: =((C30-#REF!)/#REF!)*20+100 -> #REF! | F30: 59 | G30: =LOOKUP(F30,#REF!,#REF!) -> #REF! | H30: =((F30-#REF!)/#REF!)*20+100 -> #REF! | I30: 94 | J30: =LOOKUP(I30,#REF!,#REF!) -> #REF! | K30: =((I30-#REF!)/#REF!)*20+100 -> #REF! | L30: =SUM(C30,F30,I30) -> 250 | M30: =SUM(E30,H30,K30) -> #REF! | N30: =RANK(L30,$L$4:$L$39) -> 6 | O30: 25 | P30: 22 | Q30: =(SUM(O30:P30)) -> 47 | R30: =SUM(L30,Q30) -> 297 | S30: =RANK(R30,$R$4:$R$39) -> 8 | U30: 최고점
A31: 28 | B31: 이중현 | C31: 98 | D31: =LOOKUP(C31,#REF!,#REF!) -> #REF! | E31: =((C31-#REF!)/#REF!)*20+100 -> #REF! | F31: 80 | G31: =LOOKUP(F31,#REF!,#REF!) -> #REF! | H31: =((F31-#REF!)/#REF!)*20+100 -> #REF! | I31: 91 | J31: =LOOKUP(I31,#REF!,#REF!) -> #REF! | K31: =((I31-#REF!)/#REF!)*20+100 -> #REF! | L31: =SUM(C31,F31,I31) -> 269 | M31: =SUM(E31,H31,K31) -> #REF! | N31: =RANK(L31,$L$4:$L$39) -> 3 | O31: 44 | P31: 47 | Q31: =(SUM(O31:P31)) -> 91 | R31: =SUM(L31,Q31) -> 360 | S31: =RANK(R31,$R$4:$R$39) -> 3 | U31: =MAX(R4:R39) -> 370
A32: 29 | B32: 이한택 | C32: 22 | D32: =LOOKUP(C32,#REF!,#REF!) -> #REF! | E32: =((C32-#REF!)/#REF!)*20+100 -> #REF! | F32: 12 | G32: =LOOKUP(F32,#REF!,#REF!) -> #REF! | H32: =((F32-#REF!)/#REF!)*20+100 -> #REF! | I32: 57 | J32: =LOOKUP(I32,#REF!,#REF!) -> #REF! | K32: =((I32-#REF!)/#REF!)*20+100 -> #REF! | L32: =SUM(C32,F32,I32) -> 91 | M32: =SUM(E32,H32,K32) -> #REF! | N32: =RANK(L32,$L$4:$L$39) -> 35 | O32: 41 | P32: 18 | Q32: =(SUM(O32:P32)) -> 59 | R32: =SUM(L32,Q32) -> 150 | S32: =RANK(R32,$R$4:$R$39) -> 33
A33: 30 | B33: 이호선 | C33: 75 | D33: =LOOKUP(C33,#REF!,#REF!) -> #REF! | E33: =((C33-#REF!)/#REF!)*20+100 -> #REF! | F33: 7 | G33: =LOOKUP(F33,#REF!,#REF!) -> #REF! | H33: =((F33-#REF!)/#REF!)*20+100 -> #REF! | I33: 56 | J33: =LOOKUP(I33,#REF!,#REF!) -> #REF! | K33: =((I33-#REF!)/#REF!)*20+100 -> #REF! | L33: =SUM(C33,F33,I33) -> 138 | M33: =SUM(E33,H33,K33) -> #REF! | N33: =RANK(L33,$L$4:$L$39) -> 30 | O33: 4 | P33: 9 | Q33: =(SUM(O33:P33)) -> 13 | R33: =SUM(L33,Q33) -> 151 | S33: =RANK(R33,$R$4:$R$39) -> 32 | U33: 최하점
A34: 31 | B34: 이홍노 | C34: 69 | D34: =LOOKUP(C34,#REF!,#REF!) -> #REF! | E34: =((C34-#REF!)/#REF!)*20+100 -> #REF! | F34: 40 | G34: =LOOKUP(F34,예상등급!$D$19:$D$27,예상등급!$E$19:$E$27) -> 1 | H34: =((F34-예상등급!#REF!)/예상등급!#REF!)*20+100 -> #REF! | I34: 39 | J34: =LOOKUP(I34,#REF!,#REF!) -> #REF! | K34: =((I34-#REF!)/#REF!)*20+100 -> #REF! | L34: =SUM(C34,F34,I34) -> 148 | M34: =SUM(E34,H34,K34) -> #REF! | N34: =RANK(L34,$L$4:$L$39) -> 28 | O34: 7 | P34: 19 | Q34: =(SUM(O34:P34)) -> 26 | R34: =SUM(L34,Q34) -> 174 | S34: =RANK(R34,$R$4:$R$39) -> 28 | U34: =MIN(R4:R39) -> 115
A35: 32 | B35: 정성훈 | C35: 97 | D35: =LOOKUP(C35,#REF!,#REF!) -> #REF! | E35: =((C35-#REF!)/#REF!)*20+100 -> #REF! | F35: 32 | G35: =LOOKUP(F35,#REF!,#REF!) -> #REF! | H35: =((F35-#REF!)/#REF!)*20+100 -> #REF! | I35: 70 | J35: =LOOKUP(I35,#REF!,#REF!) -> #REF! | K35: =((I35-#REF!)/#REF!)*20+100 -> #REF! | L35: =SUM(C35,F35,I35) -> 199 | M35: =SUM(E35,H35,K35) -> #REF! | N35: =RANK(L35,$L$4:$L$39) -> 17 | O35: 8 | P35: 31 | Q35: =(SUM(O35:P35)) -> 39 | R35: =SUM(L35,Q35) -> 238 | S35: =RANK(R35,$R$4:$R$39) -> 22
A36: 33 | B36: 지성겸 | C36: 20 | D36: =LOOKUP(C36,#REF!,#REF!) -> #REF! | E36: =((C36-#REF!)/#REF!)*20+100 -> #REF! | F36: 25 | G36: =LOOKUP(F36,#REF!,#REF!) -> #REF! | H36: =((F36-#REF!)/#REF!)*20+100 -> #REF! | I36: 74 | J36: =LOOKUP(I36,#REF!,#REF!) -> #REF! | K36: =((I36-#REF!)/#REF!)*20+100 -> #REF! | L36: =SUM(C36,F36,I36) -> 119 | M36: =SUM(E36,H36,K36) -> #REF! | N36: =RANK(L36,$L$4:$L$39) -> 31 | O36: 24 | P36: 22 | Q36: =(SUM(O36:P36)) -> 46 | R36: =SUM(L36,Q36) -> 165 | S36: =RANK(R36,$R$4:$R$39) -> 30
A37: 34 | B37: 최성열 | C37: 100 | D37: =LOOKUP(C37,예상등급!$A$5:$A$13,예상등급!$B$5:$B$13) -> 1 | E37: =((C37-예상등급!#REF!)/예상등급!#REF!)*20+100 -> #REF! | F37: 96 | G37: =LOOKUP(F37,예상등급!$D$19:$D$27,예상등급!$E$19:$E$27) -> 1 | H37: =((F37-예상등급!#REF!)/예상등급!#REF!)*20+100 -> #REF! | I37: 92 | J37: =LOOKUP(I37,#REF!,#REF!) -> #REF! | K37: =((I37-#REF!)/#REF!)*20+100 -> #REF! | L37: =SUM(C37,F37,I37) -> 288 | M37: =SUM(E37,H37,K37) -> #REF! | N37: =RANK(L37,$L$4:$L$39) -> 1 | O37: 47 | P37: 31 | Q37: =(SUM(O37:P37)) -> 78 | R37: =SUM(L37,Q37) -> 366 | S37: =RANK(R37,$R$4:$R$39) -> 2
A38: 35 | B38: 한동국 | C38: 100 | D38: =LOOKUP(C38,#REF!,#REF!) -> #REF! | E38: =((C38-#REF!)/#REF!)*20+100 -> #REF! | F38: 74 | G38: =LOOKUP(F38,#REF!,#REF!) -> #REF! | H38: =((F38-#REF!)/#REF!)*20+100 -> #REF! | I38: 91 | J38: =LOOKUP(I38,#REF!,#REF!) -> #REF! | K38: =((I38-#REF!)/#REF!)*20+100 -> #REF! | L38: =SUM(C38,F38,I38) -> 265 | M38: =SUM(E38,H38,K38) -> #REF! | N38: =RANK(L38,$L$4:$L$39) -> 4 | O38: 50 | P38: 41 | Q38: =(SUM(O38:P38)) -> 91 | R38: =SUM(L38,Q38) -> 356 | S38: =RANK(R38,$R$4:$R$39) -> 4
A39: 36 | B39: 호수빈 | C39: 64 | D39: =LOOKUP(C39,#REF!,#REF!) -> #REF! | E39: =((C39-#REF!)/#REF!)*20+100 -> #REF! | F39: 37 | G39: =LOOKUP(F39,#REF!,#REF!) -> #REF! | H39: =((F39-#REF!)/#REF!)*20+100 -> #REF! | I39: 68 | J39: =LOOKUP(I39,#REF!,#REF!) -> #REF! | K39: =((I39-#REF!)/#REF!)*20+100 -> #REF! | L39: =SUM(C39,F39,I39) -> 169 | M39: =SUM(E39,H39,K39) -> #REF! | N39: =RANK(L39,$L$4:$L$39) -> 26 | O39: 6 | P39: 22 | Q39: =(SUM(O39:P39)) -> 28 | R39: =SUM(L39,Q39) -> 197 | S39: =RANK(R39,$R$4:$R$39) -> 25
A40: 총점 | C40: =SUM(C4:C39) -> 2805 | D40: =SUM(D4:D39) -> #REF! | E40: =SUM(E4:E39) -> #REF! | F40: =SUM(F4:F39) -> 1554 | G40: =SUM(G4:G39) -> #REF! | H40: =SUM(H4:H39) -> #REF! | I40: =SUM(I4:I39) -> 2513 | J40: =SUM(J4:J39) -> #REF! | ... M40: =SUM(M4:M39) -> #REF! | O40: =SUM(O4:O39) -> 910 | P40: =SUM(P4:P39) -> 947 | Q40: =SUM(Q4:Q39) -> 1857 | R40: =SUM(R4:R39) -> 8729
...

Sheet 3-7
A1: 수능모의 평가 3학년 07반
A2: 실시일 : 2014. 10. 7
A3: 번 호 | B3: 성 명 | C3: 언어 | D3: 등급 | E3: 표준점수 | F3: 수리 | G3: 등급 | H3: 표준점수 | I3: 외국어 | J3: 등급 | K3: 표준점수 | L3: 언수외 소 계 | M3: 언수외 표준소계 | N3: 언수외석 차 | O3: 탐구영역 | Q3: 탐구소계 | R3: 총점 | S3: 반석차 | U3: 누계표
A4: 1 | B4: 고영승 | C4: 98 | D4: =LOOKUP(C4,#REF!,#REF!) -> #REF! | E4: =((C4-#REF!)/#REF!)*20+100 -> #REF! | F4: 88 | G4: =LOOKUP(F4,#REF!,#REF!) -> #REF! | H4: =((F4-#REF!)/#REF!)*20+100 -> #REF! | I4: 92 | J4: =LOOKUP(I4,#REF!,#REF!) -> #REF! | K4: =((I4-#REF!)/#REF!)*20+100 -> #REF! | L4: =SUM(C4,F4,I4) -> 278 | M4: =SUM(E4,H4,K4) -> #REF! | N4: =RANK(L4,$L$4:$L$40) -> 1 | O4: 47 | P4: 44 | Q4: =(SUM(O4:P4)) -> 91 | R4: =SUM(L4,Q4) -> 369 | S4: =RANK(R4,$R$4:$R$40) -> 1 | U4: 400 | W4: 399
A5: 2 | B5: 고영훈 | C5: 93 | D5: =LOOKUP(C5,#REF!,#REF!) -> #REF! | E5: =((C5-#REF!)/#REF!)*20+100 -> #REF! | F5: 73 | G5: =LOOKUP(F5,#REF!,#REF!) -> #REF! | H5: =((F5-#REF!)/#REF!)*20+100 -> #REF! | I5: 80 | J5: =LOOKUP(I5,#REF!,#REF!) -> #REF! | K5: =((I5-#REF!)/#REF!)*20+100 -> #REF! | L5: =SUM(C5,F5,I5) -> 246 | M5: =SUM(E5,H5,K5) -> #REF! | N5: =RANK(L5,$L$4:$L$40) -> 6 | O5: 38 | P5: 42 | Q5: =(SUM(O5:P5)) -> 80 | R5: =SUM(L5,Q5) -> 326 | S5: =RANK(R5,$R$4:$R$40) -> 4 | U5: 390 | V5: =FREQUENCY($R$4:$R$40,W4:W24) -> 0 | W5: 389
A6: 3 | B6: 금혜성 | C6: 95 | D6: =LOOKUP(C6,#REF!,#REF!) -> #REF! | E6: =((C6-#REF!)/#REF!)*20+100 -> #REF! | F6: 36 | G6: =LOOKUP(F6,#REF!,#REF!) -> #REF! | H6: =((F6-#REF!)/#REF!)*20+100 -> #REF! | I6: 77 | J6: =LOOKUP(I6,#REF!,#REF!) -> #REF! | K6: =((I6-#REF!)/#REF!)*20+100 -> #REF! | L6: =SUM(C6,F6,I6) -> 208 | M6: =SUM(E6,H6,K6) -> #REF! | N6: =RANK(L6,$L$4:$L$40) -> 14 | O6: 33 | P6: 31 | Q6: =(SUM(O6:P6)) -> 64 | R6: =SUM(L6,Q6) -> 272 | S6: =RANK(R6,$R$4:$R$40) -> 10 | U6: 380 | V6: =FREQUENCY($R$4:$R$40,W5:W25) -> 0 | W6: 379
A7: 4 | B7: 김강건 | C7: 97 | D7: =LOOKUP(C7,#REF!,#REF!) -> #REF! | E7: =((C7-#REF!)/#REF!)*20+100 -> #REF! | F7: 81 | G7: =LOOKUP(F7,#REF!,#REF!) -> #REF! | H7: =((F7-#REF!)/#REF!)*20+100 -> #REF! | I7: 94 | J7: =LOOKUP(I7,#REF!,#REF!) -> #REF! | K7: =((I7-#REF!)/#REF!)*20+100 -> #REF! | L7: =SUM(C7,F7,I7) -> 272 | M7: =SUM(E7,H7,K7) -> #REF! | N7: =RANK(L7,$L$4:$L$40) -> 2 | O7: 36 | P7: 46 | Q7: =(SUM(O7:P7)) -> 82 | R7: =SUM(L7,Q7) -> 354 | S7: =RANK(R7,$R$4:$R$40) -> 2 | U7: 370 | V7: =FREQUENCY($R$4:$R$40,W6:W26) -> 0 | W7: 369
A8: 5 | B8: 김건식 | C8: 20 | D8: =LOOKUP(C8,#REF!,#REF!) -> #REF! | E8: =((C8-#REF!)/#REF!)*20+100 -> #REF! | F8: 44 | G8: =LOOKUP(F8,#REF!,#REF!) -> #REF! | H8: =((F8-#REF!)/#REF!)*20+100 -> #REF! | I8: 34 | J8: =LOOKUP(I8,#REF!,#REF!) -> #REF! | K8: =((I8-#REF!)/#REF!)*20+100 -> #REF! | L8: =SUM(C8,F8,I8) -> 98 | M8: =SUM(E8,H8,K8) -> #REF! | N8: =RANK(L8,$L$4:$L$40) -> 32 | O8: 18 | P8: 6 | Q8: =(SUM(O8:P8)) -> 24 | R8: =SUM(L8,Q8) -> 122 | S8: =RANK(R8,$R$4:$R$40) -> 32 | U8: 360 | V8: =FREQUENCY($R$4:$R$40,W7:W27) -> 1 | W8: 359
A9: 6 | B9: 김기배 | C9: 71 | D9: =LOOKUP(C9,#REF!,#REF!) -> #REF! | E9: =((C9-#REF!)/#REF!)*20+100 -> #REF! | F9: 38 | G9: =LOOKUP(F9,#REF!,#REF!) -> #REF! | H9: =((F9-#REF!)/#REF!)*20+100 -> #REF! | I9: 47 | J9: =LOOKUP(I9,#REF!,#REF!) -> #REF! | K9: =((I9-#REF!)/#REF!)*20+100 -> #REF! | L9: =SUM(C9,F9,I9) -> 156 | M9: =SUM(E9,H9,K9) -> #REF! | N9: =RANK(L9,$L$4:$L$40) -> 28 | O9: 37 | P9: 33 | Q9: =(SUM(O9:P9)) -> 70 | R9: =SUM(L9,Q9) -> 226 | S9: =RANK(R9,$R$4:$R$40) -> 22 | U9: 350 | V9: =FREQUENCY($R$4:$R$40,W8:W28) -> 1 | W9: 349
A10: 7 | B10: 김도훈 | C10: 84 | D10: =LOOKUP(C10,#REF!,#REF!) -> #REF! | E10: =((C10-#REF!)/#REF!)*20+100 -> #REF! | F10: 51 | G10: =LOOKUP(F10,#REF!,#REF!) -> #REF! | H10: =((F10-#REF!)/#REF!)*20+100 -> #REF! | I10: 82 | J10: =LOOKUP(I10,#REF!,#REF!) -> #REF! | K10: =((I10-#REF!)/#REF!)*20+100 -> #REF! | L10: =SUM(C10,F10,I10) -> 217 | M10: =SUM(E10,H10,K10) -> #REF! | N10: =RANK(L10,$L$4:$L$40) -> 11 | O10: 20 | P10: 18 | Q10: =(SUM(O10:P10)) -> 38 | R10: =SUM(L10,Q10) -> 255 | S10: =RANK(R10,$R$4:$R$40) -> 16 | U10: 340 | V10: =FREQUENCY($R$4:$R$40,W9:W29) -> 1 | W10: 339
A11: 8 | B11: 김민후 | C11: 75 | D11: =LOOKUP(C11,#REF!,#REF!) -> #REF! | E11: =((C11-#REF!)/#REF!)*20+100 -> #REF! | F11: 30 | G11: =LOOKUP(F11,#REF!,#REF!) -> #REF! | H11: =((F11-#REF!)/#REF!)*20+100 -> #REF! | I11: 81 | J11: =LOOKUP(I11,#REF!,#REF!) -> #REF! | K11: =((I11-#REF!)/#REF!)*20+100 -> #REF! | L11: =SUM(C11,F11,I11) -> 186 | M11: =SUM(E11,H11,K11) -> #REF! | N11: =RANK(L11,$L$4:$L$40) -> 22 | O11: 16 | P11: 18 | Q11: =(SUM(O11:P11)) -> 34 | R11: =SUM(L11,Q11) -> 220 | S11: =RANK(R11,$R$4:$R$40) -> 25 | U11: 330 | V11: =FREQUENCY($R$4:$R$40,W10:W30) -> 0 | W11: 329
A12: 9 | B12: 김사빈 | C12: 96 | D12: =LOOKUP(C12,#REF!,#REF!) -> #REF! | E12: =((C12-#REF!)/#REF!)*20+100 -> #REF! | F12: 55 | G12: =LOOKUP(F12,#REF!,#REF!) -> #REF! | H12: =((F12-#REF!)/#REF!)*20+100 -> #REF! | I12: 38 | J12: =LOOKUP(I12,#REF!,#REF!) -> #REF! | K12: =((I12-#REF!)/#REF!)*20+100 -> #REF! | L12: =SUM(C12,F12,I12) -> 189 | M12: =SUM(E12,H12,K12) -> #REF! | N12: =RANK(L12,$L$4:$L$40) -> 21 | O12: 33 | P12: 27 | Q12: =(SUM(O12:P12)) -> 60 | R12: =SUM(L12,Q12) -> 249 | S12: =RANK(R12,$R$4:$R$40) -> 18 | U12: 320 | V12: =FREQUENCY($R$4:$R$40,W11:W31) -> 2 | W12: 319
A13: 10 | B13: 김주성 | C13: 80 | D13: =LOOKUP(C13,#REF!,#REF!) -> #REF! | E13: =((C13-#REF!)/#REF!)*20+100 -> #REF! | F13: 38 | G13: =LOOKUP(F13,#REF!,#REF!) -> #REF! | H13: =((F13-#REF!)/#REF!)*20+100 -> #REF! | I13: 47 | J13: =LOOKUP(I13,#REF!,#REF!) -> #REF! | K13: =((I13-#REF!)/#REF!)*20+100 -> #REF! | L13: =SUM(C13,F13,I13) -> 165 | M13: =SUM(E13,H13,K13) -> #REF! | N13: =RANK(L13,$L$4:$L$40) -> 26 | O13: 28 | P13: 15 | Q13: =(SUM(O13:P13)) -> 43 | R13: =SUM(L13,Q13) -> 208 | S13: =RANK(R13,$R$4:$R$40) -> 28 | U13: 310 | V13: =FREQUENCY($R$4:$R$40,W12:W32) -> 1 | W13: 309
A14: 11 | B14: 김지운 | C14: 81 | D14: =LOOKUP(C14,#REF!,#REF!) -> #REF! | E14: =((C14-#REF!)/#REF!)*20+100 -> #REF! | F14: 37 | G14: =LOOKUP(F14,#REF!,#REF!) -> #REF! | H14: =((F14-#REF!)/#REF!)*20+100 -> #REF! | I14: 74 | J14: =LOOKUP(I14,#REF!,#REF!) -> #REF! | K14: =((I14-#REF!)/#REF!)*20+100 -> #REF! | L14: =SUM(C14,F14,I14) -> 192 | M14: =SUM(E14,H14,K14) -> #REF! | N14: =RANK(L14,$L$4:$L$40) -> 18 | O14: 18 | P14: 21 | Q14: =(SUM(O14:P14)) -> 39 | R14: =SUM(L14,Q14) -> 231 | S14: =RANK(R14,$R$4:$R$40) -> 20 | U14: 300 | V14: =FREQUENCY($R$4:$R$40,W13:W33) -> 0 | W14: 299
A15: 12 | B15: 김희수 | C15: 57 | D15: =LOOKUP(C15,#REF!,#REF!) -> #REF! | E15: =((C15-#REF!)/#REF!)*20+100 -> #REF! | F15: 29 | G15: =LOOKUP(F15,#REF!,#REF!) -> #REF! | H15: =((F15-#REF!)/#REF!)*20+100 -> #REF! | I15: 86 | J15: =LOOKUP(I15,#REF!,#REF!) -> #REF! | K15: =((I15-#REF!)/#REF!)*20+100 -> #REF! | L15: =SUM(C15,F15,I15) -> 172 | M15: =SUM(E15,H15,K15) -> #REF! | N15: =RANK(L15,$L$4:$L$40) -> 24 | O15: 21 | P15: 16 | Q15: =(SUM(O15:P15)) -> 37 | R15: =SUM(L15,Q15) -> 209 | S15: =RANK(R15,$R$4:$R$40) -> 27 | U15: 290 | V15: =FREQUENCY($R$4:$R$40,W14:W34) -> 3 | W15: 289
A16: 13 | B16: 노진영 | C16: 88 | D16: =LOOKUP(C16,#REF!,#REF!) -> #REF! | E16: =((C16-#REF!)/#REF!)*20+100 -> #REF! | F16: 80 | G16: =LOOKUP(F16,#REF!,#REF!) -> #REF! | H16: =((F16-#REF!)/#REF!)*20+100 -> #REF! | I16: 96 | J16: =LOOKUP(I16,#REF!,#REF!) -> #REF! | K16: =((I16-#REF!)/#REF!)*20+100 -> #REF! | L16: =SUM(C16,F16,I16) -> 264 | M16: =SUM(E16,H16,K16) -> #REF! | N16: =RANK(L16,$L$4:$L$40) -> 3 | O16: 38 | P16: 44 | Q16: =(SUM(O16:P16)) -> 82 | R16: =SUM(L16,Q16) -> 346 | S16: =RANK(R16,$R$4:$R$40) -> 3 | U16: 280 | V16: =FREQUENCY($R$4:$R$40,W15:W35) -> 0 | W16: 279
... A18: 15 | B18: 박성은 | C18: 83 | D18: =LOOKUP(C18,#REF!,#REF!) -> #REF! | E18: =((C18-#REF!)/#REF!)*20+100 -> #REF! | F18: 30 | G18: =LOOKUP(F18,#REF!,#REF!) -> #REF! | H18: =((F18-#REF!)/#REF!)*20+100 -> #REF! | I18: 61 | J18: =LOOKUP(I18,#REF!,#REF!) -> #REF! | K18: =((I18-#REF!)/#REF!)*20+100 -> #REF! | L18: =SUM(C18,F18,I18) -> 174 | M18: =SUM(E18,H18,K18) -> #REF! | N18: =RANK(L18,$L$4:$L$40) -> 23 | O18: 33 | P18: 15 | Q18: =(SUM(O18:P18)) -> 48 | R18: =SUM(L18,Q18) -> 222 | S18: =RANK(R18,$R$4:$R$40) -> 23 | U18: 260 | V18: =FREQUENCY($R$4:$R$40,W17:W37) -> 4 | W18: 259
A19: 16 | B19: 서동규 | C19: 34 | D19: =LOOKUP(C19,#REF!,#REF!) -> #REF! | E19: =((C19-#REF!)/#REF!)*20+100 -> #REF! | F19: 15 | G19: =LOOKUP(F19,#REF!,#REF!) -> #REF! | H19: =((F19-#REF!)/#REF!)*20+100 -> #REF! | I19: 28 | J19: =LOOKUP(I19,#REF!,#REF!) -> #REF! | K19: =((I19-#REF!)/#REF!)*20+100 -> #REF! | L19: =SUM(C19,F19,I19) -> 77 | M19: =SUM(E19,H19,K19) -> #REF! | N19: =RANK(L19,$L$4:$L$40) -> 33 | O19: 11 | P19: 20 | Q19: =(SUM(O19:P19)) -> 31 | R19: =SUM(L19,Q19) -> 108 | S19: =RANK(R19,$R$4:$R$40) -> 33 | U19: 250 | V19: =FREQUENCY($R$4:$R$40,W18:W40) -> 3 | W19: 249
A20: 17 | B20: 손우용 | C20: 98 | D20: =LOOKUP(C20,#REF!,#REF!) -> #REF! | E20: =((C20-#REF!)/#REF!)*20+100 -> #REF! | F20: 42 | G20: =LOOKUP(F20,#REF!,#REF!) -> #REF! | H20: =((F20-#REF!)/#REF!)*20+100 -> #REF! | I20: 51 | J20: =LOOKUP(I20,#REF!,#REF!) -> #REF! | K20: =((I20-#REF!)/#REF!)*20+100 -> #REF! | L20: =SUM(C20,F20,I20) -> 191 | M20: =SUM(E20,H20,K20) -> #REF! | N20: =RANK(L20,$L$4:$L$40) -> 19 | O20: 16 | P20: 24 | Q20: =(SUM(O20:P20)) -> 40 | R20: =SUM(L20,Q20) -> 231 | S20: =RANK(R20,$R$4:$R$40) -> 20 | U20: 240 | V20: =FREQUENCY($R$4:$R$40,W19:W40) -> 2 | W20: 239
A21: 18 | B21: 심재형 | C21: 95 | D21: =LOOKUP(C21,#REF!,#REF!) -> #REF! | E21: =((C21-#REF!)/#REF!)*20+100 -> #REF! | F21: 28 | G21: =LOOKUP(F21,#REF!,#REF!) -> #REF! | H21: =((F21-#REF!)/#REF!)*20+100 -> #REF! | I21: 67 | J21: =LOOKUP(I21,#REF!,#REF!) -> #REF! | K21: =((I21-#REF!)/#REF!)*20+100 -> #REF! | L21: =SUM(C21,F21,I21) -> 190 | M21: =SUM(E21,H21,K21) -> #REF! | N21: =RANK(L21,$L$4:$L$40) -> 20 | O21: 39 | P21: 35 | Q21: =(SUM(O21:P21)) -> 74 | R21: =SUM(L21,Q21) -> 264 | S21: =RANK(R21,$R$4:$R$40) -> 13 | U21: 230 | V21: =FREQUENCY($R$4:$R$40,W20:W40) -> 2 | W21: 229
A22: 19 | B22: 유기덕 | C22: 75 | D22: =LOOKUP(C22,#REF!,#REF!) -> #REF! | E22: =((C22-#REF!)/#REF!)*20+100 -> #REF! | F22: 30 | G22: =LOOKUP(F22,#REF!,#REF!) -> #REF! | H22: =((F22-#REF!)/#REF!)*20+100 -> #REF! | I22: 51 | J22: =LOOKUP(I22,#REF!,#REF!) -> #REF! | K22: =((I22-#REF!)/#REF!)*20+100 -> #REF! | L22: =SUM(C22,F22,I22) -> 156 | M22: =SUM(E22,H22,K22) -> #REF! | N22: =RANK(L22,$L$4:$L$40) -> 28 | O22: 41 | P22: 16 | Q22: =(SUM(O22:P22)) -> 57 | R22: =SUM(L22,Q22) -> 213 | S22: =RANK(R22,$R$4:$R$40) -> 26 | U22: 220 | V22: =FREQUENCY($R$4:$R$40,W21:W41) -> 4 | W22: 219
A23: 20 | B23: 유덕호 | C23: 93 | D23: =LOOKUP(C23,#REF!,#REF!) -> #REF! | E23: =((C23-#REF!)/#REF!)*20+100 -> #REF! | F23: 60 | G23: =LOOKUP(F23,#REF!,#REF!) -> #REF! | H23: =((F23-#REF!)/#REF!)*20+100 -> #REF! | I23: 75 | J23: =LOOKUP(I23,#REF!,#REF!) -> #REF! | K23: =((I23-#REF!)/#REF!)*20+100 -> #REF! | L23: =SUM(C23,F23,I23) -> 228 | M23: =SUM(E23,H23,K23) -> #REF! | N23: =RANK(L23,$L$4:$L$40) -> 8 | O23: 16 | P23: 12 | Q23: =(SUM(O23:P23)) -> 28 | R23: =SUM(L23,Q23) -> 256 | S23: =RANK(R23,$R$4:$R$40) -> 15 | U23: 210 | V23: =FREQUENCY($R$4:$R$40,W22:W42) -> 1 | W23: 209
A24: 21 | B24: 윤명혁 | C24: 92 | D24: =LOOKUP(C24,#REF!,#REF!) -> #REF! | E24: =((C24-#REF!)/#REF!)*20+100 -> #REF! | F24: 78 | G24: =LOOKUP(F24,#REF!,#REF!) -> #REF! | H24: =((F24-#REF!)/#REF!)*20+100 -> #REF! | I24: 77 | J24: =LOOKUP(I24,#REF!,#REF!) -> #REF! | K24: =((I24-#REF!)/#REF!)*20+100 -> #REF! | L24: =SUM(C24,F24,I24) -> 247 | M24: =SUM(E24,H24,K24) -> #REF! | N24: =RANK(L24,$L$4:$L$40) -> 5 | O24: 30 | P24: 41 | Q24: =(SUM(O24:P24)) -> 71 | R24: =SUM(L24,Q24) -> 318 | S24: =RANK(R24,$R$4:$R$40) -> 6 | U24: 200 | V24: =FREQUENCY($R$4:$R$40,W23:W43) -> 2 | W24: 199
A25: 22 | B25: 윤민기 | C25: 88 | D25: =LOOKUP(C25,#REF!,#REF!) -> #REF! | E25: =((C25-#REF!)/#REF!)*20+100 -> #REF! | F25: 41 | G25: =LOOKUP(F25,#REF!,#REF!) -> #REF! | H25: =((F25-#REF!)/#REF!)*20+100 -> #REF! | I25: 77 | J25: =LOOKUP(I25,#REF!,#REF!) -> #REF! | K25: =((I25-#REF!)/#REF!)*20+100 -> #REF! | L25: =SUM(C25,F25,I25) -> 206 | M25: =SUM(E25,H25,K25) -> #REF! | N25: =RANK(L25,$L$4:$L$40) -> 15 | O25: 32 | P25: 22 | Q25: =(SUM(O25:P25)) -> 54 | R25: =SUM(L25,Q25) -> 260 | S25: =RANK(R25,$R$4:$R$40) -> 14 | U25: 190 | V25: =FREQUENCY($R$4:$R$40,W24:W44) -> 0 | W25: 189
A26: 23 | B26: 이규원 | C26: 95 | D26: =LOOKUP(C26,#REF!,#REF!) -> #REF! | E26: =((C26-#REF!)/#REF!)*20+100 -> #REF! | F26: 21 | G26: =LOOKUP(F26,#REF!,#REF!) -> #REF! | H26: =((F26-#REF!)/#REF!)*20+100 -> #REF! | I26: 47 | J26: =LOOKUP(I26,#REF!,#REF!) -> #REF! | K26: =((I26-#REF!)/#REF!)*20+100 -> #REF! | L26: =SUM(C26,F26,I26) -> 163 | M26: =SUM(E26,H26,K26) -> #REF! | N26: =RANK(L26,$L$4:$L$40) -> 27 | O26: 5 | P26: 11 | Q26: =(SUM(O26:P26)) -> 16 | R26: =SUM(L26,Q26) -> 179 | S26: =RANK(R26,$R$4:$R$40) -> 29 | U26: 190이하 | V26: =FREQUENCY($R$4:$R$40,W25:W45) -> 9
A27: 24 | B27: 이상진 | C27: 30 | D27: =LOOKUP(C27,#REF!,#REF!) -> #REF! | E27: =((C27-#REF!)/#REF!)*20+100 -> #REF! | F27: 15 | G27: =LOOKUP(F27,#REF!,#REF!) -> #REF! | H27: =((F27-#REF!)/#REF!)*20+100 -> #REF! | I27: 29 | J27: =LOOKUP(I27,#REF!,#REF!) -> #REF! | K27: =((I27-#REF!)/#REF!)*20+100 -> #REF! | L27: =SUM(C27,F27,I27) -> 74 | M27: =SUM(E27,H27,K27) -> #REF! | N27: =RANK(L27,$L$4:$L$40) -> 34 | O27: 13 | P27: 10 | Q27: =(SUM(O27:P27)) -> 23 | R27: =SUM(L27,Q27) -> 97 | S27: =RANK(R27,$R$4:$R$40) -> 34 | U27: 합계 | V27: =SUM(V4:V26) -> 37
A28: 25 | B28: 이영찬 | C28: 93 | D28: =LOOKUP(C28,#REF!,#REF!) -> #REF! | E28: =((C28-#REF!)/#REF!)*20+100 -> #REF! | F28: 37 | G28: =LOOKUP(F28,#REF!,#REF!) -> #REF! | H28: =((F28-#REF!)/#REF!)*20+100 -> #REF! | I28: 69 | J28: =LOOKUP(I28,#REF!,#REF!) -> #REF! | K28: =((I28-#REF!)/#REF!)*20+100 -> #REF! | L28: =SUM(C28,F28,I28) -> 199 | M28: =SUM(E28,H28,K28) -> #REF! | N28: =RANK(L28,$L$4:$L$40) -> 17 | O28: 25 | P28: 22 | Q28: =(SUM(O28:P28)) -> 47 | R28: =SUM(L28,Q28) -> 246 | S28: =RANK(R28,$R$4:$R$40) -> 19
A29: 26 | B29: 이재원 | C29: 88 | D29: =LOOKUP(C29,#REF!,#REF!) -> #REF! | E29: =((C29-#REF!)/#REF!)*20+100 -> #REF! | F29: 41 | G29: =LOOKUP(F29,#REF!,#REF!) -> #REF! | H29: =((F29-#REF!)/#REF!)*20+100 -> #REF! | I29: 73 | J29: =LOOKUP(I29,#REF!,#REF!) -> #REF! | K29: =((I29-#REF!)/#REF!)*20+100 -> #REF! | L29: =SUM(C29,F29,I29) -> 202 | M29: =SUM(E29,H29,K29) -> #REF! | N29: =RANK(L29,$L$4:$L$40) -> 16 | O29: 24 | P29: 26 | Q29: =(SUM(O29:P29)) -> 50 | R29: =SUM(L29,Q29) -> 252 | S29: =RANK(R29,$R$4:$R$40) -> 17
A30: 27 | B30: 이종관 | C30: 86 | D30: =LOOKUP(C30,#REF!,#REF!) -> #REF! | E30: =((C30-#REF!)/#REF!)*20+100 -> #REF! | F30: 53 | G30: =LOOKUP(F30,#REF!,#REF!) -> #REF! | H30: =((F30-#REF!)/#REF!)*20+100 -> #REF! | I30: 82 | J30: =LOOKUP(I30,#REF!,#REF!) -> #REF! | K30: =((I30-#REF!)/#REF!)*20+100 -> #REF! | L30: =SUM(C30,F30,I30) -> 221 | M30: =SUM(E30,H30,K30) -> #REF! | N30: =RANK(L30,$L$4:$L$40) -> 9 | O30: 38 | P30: 34 | Q30: =(SUM(O30:P30)) -> 72 | R30: =SUM(L30,Q30) -> 293 | S30: =RANK(R30,$R$4:$R$40) -> 9 | U30: 최고점
A31: 28 | B31: 이준영 | C31: 98 | D31: =LOOKUP(C31,#REF!,#REF!) -> #REF! | E31: =((C31-#REF!)/#REF!)*20+100 -> #REF! | F31: 48 | G31: =LOOKUP(F31,#REF!,#REF!) -> #REF! | H31: =((F31-#REF!)/#REF!)*20+100 -> #REF! | I31: 73 | J31: =LOOKUP(I31,#REF!,#REF!) -> #REF! | K31: =((I31-#REF!)/#REF!)*20+100 -> #REF! | L31: =SUM(C31,F31,I31) -> 219 | M31: =SUM(E31,H31,K31) -> #REF! | N31: =RANK(L31,$L$4:$L$40) -> 10 | O31: 20 | P31: 30 | Q31: =(SUM(O31:P31)) -> 50 | R31: =SUM(L31,Q31) -> 269 | S31: =RANK(R31,$R$4:$R$40) -> 11 | U31: =MAX(R4:R40) -> 369
A32: 29 | B32: 임한울 | C32: 18 | D32: =LOOKUP(C32,#REF!,#REF!) -> #REF! | E32: =((C32-#REF!)/#REF!)*20+100 -> #REF! | F32: 16 | G32: =LOOKUP(F32,#REF!,#REF!) -> #REF! | H32: =((F32-#REF!)/#REF!)*20+100 -> #REF! | I32: 20 | J32: =LOOKUP(I32,#REF!,#REF!) -> #REF! | K32: =((I32-#REF!)/#REF!)*20+100 -> #REF! | L32: =SUM(C32,F32,I32) -> 54 | M32: =SUM(E32,H32,K32) -> #REF! | N32: =RANK(L32,$L$4:$L$40) -> 37 | O32: 6 | P32: 20 | Q32: =(SUM(O32:P32)) -> 26 | R32: =SUM(L32,Q32) -> 80 | S32: =RANK(R32,$R$4:$R$40) -> 36
A33: 30 | B33: 전형남 | C33: 85 | D33: =LOOKUP(C33,#REF!,#REF!) -> #REF! | E33: =((C33-#REF!)/#REF!)*20+100 -> #REF! | F33: 34 | G33: =LOOKUP(F33,#REF!,#REF!) -> #REF! | H33: =((F33-#REF!)/#REF!)*20+100 -> #REF! | I33: 51 | J33: =LOOKUP(I33,#REF!,#REF!) -> #REF! | K33: =((I33-#REF!)/#REF!)*20+100 -> #REF! | L33: =SUM(C33,F33,I33) -> 170 | M33: =SUM(E33,H33,K33) -> #REF! | N33: =RANK(L33,$L$4:$L$40) -> 25 | O33: 24 | P33: 28 | Q33: =(SUM(O33:P33)) -> 52 | R33: =SUM(L33,Q33) -> 222 | S33: =RANK(R33,$R$4:$R$40) -> 23 | U33: 최하점
A34: 31 | B34: 정상민 | C34: 100 | D34: =LOOKUP(C34,#REF!,#REF!) -> #REF! | E34: =((C34-#REF!)/#REF!)*20+100 -> #REF! | F34: 63 | G34: =LOOKUP(F34,#REF!,#REF!) -> #REF! | H34: =((F34-#REF!)/#REF!)*20+100 -> #REF! | I34: 94 | J34: =LOOKUP(I34,#REF!,#REF!) -> #REF! | K34: =((I34-#REF!)/#REF!)*20+100 -> #REF! | L34: =SUM(C34,F34,I34) -> 257 | M34: =SUM(E34,H34,K34) -> #REF! | N34: =RANK(L34,$L$4:$L$40) -> 4 | O34: 33 | P34: 35 | Q34: =(SUM(O34:P34)) -> 68 | R34: =SUM(L34,Q34) -> 325 | S34: =RANK(R34,$R$4:$R$40) -> 5 | U34: =MIN(R4:R40) -> 76
A35: 32 | B35: 정준 | C35: 91 | D35: =LOOKUP(C35,#REF!,#REF!) -> #REF! | E35: =((C35-#REF!)/#REF!)*20+100 -> #REF! | F35: 70 | G35: =LOOKUP(F35,#REF!,#REF!) -> #REF! | H35: =((F35-#REF!)/#REF!)*20+100 -> #REF! | I35: 68 | J35: =LOOKUP(I35,#REF!,#REF!) -> #REF! | K35: =((I35-#REF!)/#REF!)*20+100 -> #REF! | L35: =SUM(C35,F35,I35) -> 229 | M35: =SUM(E35,H35,K35) -> #REF! | N35: =RANK(L35,$L$4:$L$40) -> 7 | O35: 36 | P35: 30 | Q35: =(SUM(O35:P35)) -> 66 | R35: =SUM(L35,Q35) -> 295 | S35: =RANK(R35,$R$4:$R$40) -> 8
A36: 33 | B36: 정태민 | C36: 65 | D36: =LOOKUP(C36,#REF!,#REF!) -> #REF! | E36: =((C36-#REF!)/#REF!)*20+100 -> #REF! | F36: 29 | G36: =LOOKUP(F36,#REF!,#REF!) -> #REF! | H36: =((F36-#REF!)/#REF!)*20+100 -> #REF! | I36: 50 | J36: =LOOKUP(I36,#REF!,#REF!) -> #REF! | K36: =((I36-#REF!)/#REF!)*20+100 -> #REF! | L36: =SUM(C36,F36,I36) -> 144 | M36: =SUM(E36,H36,K36) -> #REF! | N36: =RANK(L36,$L$4:$L$40) -> 30 | O36: 23 | P36: 11 | Q36: =(SUM(O36:P36)) -> 34 | R36: =SUM(L36,Q36) -> 178 | S36: =RANK(R36,$R$4:$R$40) -> 30
A37: 34 | B37: 최성일 | C37: 21 | D37: =LOOKUP(C37,#REF!,#REF!) -> #REF! | E37: =((C37-#REF!)/#REF!)*20+100 -> #REF! | F37: 12 | G37: =LOOKUP(F37,#REF!,#REF!) -> #REF! | H37: =((F37-#REF!)/#REF!)*20+100 -> #REF! | I37: 22 | J37: =LOOKUP(I37,#REF!,#REF!) -> #REF! | K37: =((I37-#REF!)/#REF!)*20+100 -> #REF! | L37: =SUM(C37,F37,I37) -> 55 | M37: =SUM(E37,H37,K37) -> #REF! | N37: =RANK(L37,$L$4:$L$40) -> 36 | O37: 10 | P37: 11 | Q37: =(SUM(O37:P37)) -> 21 | R37: =SUM(L37,Q37) -> 76 | S37: =RANK(R37,$R$4:$R$40) -> 37
A38: 35 | B38: 최윤석 | C38: 46 | D38: =LOOKUP(C38,#REF!,#REF!) -> #REF! | E38: =((C38-#REF!)/#REF!)*20+100 -> #REF! | F38: 20 | G38: =LOOKUP(F38,#REF!,#REF!) -> #REF! | H38: =((F38-#REF!)/#REF!)*20+100 -> #REF! | I38: 43 | J38: =LOOKUP(I38,#REF!,#REF!) -> #REF! | K38: =((I38-#REF!)/#REF!)*20+100 -> #REF! | L38: =SUM(C38,F38,I38) -> 109 | M38: =SUM(E38,H38,K38) -> #REF! | N38: =RANK(L38,$L$4:$L$40) -> 31 | O38: 16 | P38: 16 | Q38: =(SUM(O38:P38)) -> 32 | R38: =SUM(L38,Q38) -> 141 | S38: =RANK(R38,$R$4:$R$40) -> 31
A39: 36 | B39: 황민상 | C39: 89 | D39: =LOOKUP(C39,#REF!,#REF!) -> #REF! | E39: =((C39-#REF!)/#REF!)*20+100 -> #REF! | F39: 60 | G39: =LOOKUP(F39,#REF!,#REF!) -> #REF! | H39: =((F39-#REF!)/#REF!)*20+100 -> #REF! | I39: 68 | J39: =LOOKUP(I39,#REF!,#REF!) -> #REF! | K39: =((I39-#REF!)/#REF!)*20+100 -> #REF! | L39: =SUM(C39,F39,I39) -> 217 | M39: =SUM(E39,H39,K39) -> #REF! | N39: =RANK(L39,$L$4:$L$40) -> 11 | O39: 33 | P39: 47 | Q39: =(SUM(O39:P39)) -> 80 | R39: =SUM(L39,Q39) -> 297 | S39: =RANK(R39,$R$4:$R$40) -> 7
A40: 37 | B40: 황호현 | C40: 21 | D40: =LOOKUP(C40,#REF!,#REF!) -> #REF! | E40: =((C40-#REF!)/#REF!)*20+100 -> #REF! | F40: 15 | G40: =LOOKUP(F40,#REF!,#REF!) -> #REF! | H40: =((F40-#REF!)/#REF!)*20+100 -> #REF! | I40: 34 | J40: =LOOKUP(I40,#REF!,#REF!) -> #REF! | K40: =((I40-#REF!)/#REF!)*20+100 -> #REF! | L40: =SUM(C40,F40,I40) -> 70 | M40: =SUM(E40,H40,K40) -> #REF! | N40: =RANK(L40,$L$4:$L$40) -> 35 | O40: 6 | P40: 6 | Q40: =(SUM(O40:P40)) -> 12 | R40: =SUM(L40,Q40) -> 82 | S40: =RANK(R40,$R$4:$R$40) -> 35
A41: 총점 | C41: =SUM(C4:C40) -> 2817 | D41: =SUM(D4:D40) -> #REF! | E41: =SUM(E4:E40) -> #REF! | F41: =SUM(F4:F40) -> 1574 | G41: =SUM(G4:G40) -> #REF! | H41: =SUM(H4:H40) -> #REF! | I41: =SUM(I4:I40) -> 2320 | J41: =SUM(J4:J40) -> #REF! | ... M41: =SUM(M4:M40) -> #REF! | O41: =SUM(O4:O40) -> 937 | P41: =SUM(P4:P40) -> 912 | Q41: =SUM(Q4:Q40) -> 1849 | R41: =SUM(R4:R40) -> 8560
...

Sheet 3-8
A1: 수능모의 평가 3학년 08반
A2: 실시일 : 2014. 10. 7
A3: 번 호 | B3: 성 명 | C3: 언어 | D3: 등급 | E3: 표준점수 | F3: 수리 | G3: 등급 | H3: 표준점수 | I3: 외국어 | J3: 등급 | K3: 표준점수 | L3: 언수외 소 계 | M3: 언수외 표준소계 | N3: 언수외석 차 | O3: 탐구영역 | Q3: 탐구소계 | R3: 총점 | S3: 반석차 | U3: 누계표
A4: 1 | B4: 강민우 | C4: 98 | D4: =LOOKUP(C4,#REF!,#REF!) -> #REF! | E4: =((C4-#REF!)/#REF!)*20+100 -> #REF! | F4: 43 | G4: =LOOKUP(F4,#REF!,#REF!) -> #REF! | H4: =((F4-#REF!)/#REF!)*20+100 -> #REF! | I4: 52 | J4: =LOOKUP(I4,#REF!,#REF!) -> #REF! | K4: =((I4-#REF!)/#REF!)*20+100 -> #REF! | L4: =SUM(C4,F4,I4) -> 193 | M4: =SUM(E4,H4,K4) -> #REF! | N4: =RANK(L4,$L$4:$L$40) -> 16 | O4: 25 | P4: 30 | Q4: =(SUM(O4:P4)) -> 55 | R4: =SUM(L4,Q4) -> 248 | S4: =RANK(R4,$R$4:$R$40) -> 15 | U4: 400 | W4: 399
A5: 2 | B5: 권민표 | C5: 44 | D5: =LOOKUP(C5,#REF!,#REF!) -> #REF! | E5: =((C5-#REF!)/#REF!)*20+100 -> #REF! | F5: 44 | G5: =LOOKUP(F5,#REF!,#REF!) -> #REF! | H5: =((F5-#REF!)/#REF!)*20+100 -> #REF! | I5: 52 | J5: =LOOKUP(I5,#REF!,#REF!) -> #REF! | K5: =((I5-#REF!)/#REF!)*20+100 -> #REF! | L5: =SUM(C5,F5,I5) -> 140 | M5: =SUM(E5,H5,K5) -> #REF! | N5: =RANK(L5,$L$4:$L$40) -> 26 | O5: 18 | P5: 8 | Q5: =(SUM(O5:P5)) -> 26 | R5: =SUM(L5,Q5) -> 166 | S5: =RANK(R5,$R$4:$R$40) -> 28 | U5: 390 | V5: =FREQUENCY($R$4:$R$40,W4:W24) -> 0 | W5: 389
A6: 3 | B6: 권유안 | C6: 97 | D6: =LOOKUP(C6,예상등급!$A$5:$A$13,예상등급!$B$5:$B$13) -> 1 | E6: =((C6-예상등급!#REF!)/예상등급!#REF!)*20+100 -> #REF! | F6: 77 | G6: =LOOKUP(F6,예상등급!$D$19:$D$27,예상등급!$E$19:$E$27) -> 1 | H6: =((F6-예상등급!#REF!)/예상등급!#REF!)*20+100 -> #REF! | I6: 80 | J6: =LOOKUP(I6,#REF!,#REF!) -> #REF! | K6: =((I6-#REF!)/#REF!)*20+100 -> #REF! | L6: =SUM(C6,F6,I6) -> 254 | M6: =SUM(E6,H6,K6) -> #REF! | N6: =RANK(L6,$L$4:$L$40) -> 5 | O6: 38 | P6: 30 | Q6: =(SUM(O6:P6)) -> 68 | R6: =SUM(L6,Q6) -> 322 | S6: =RANK(R6,$R$4:$R$40) -> 4 | U6: 380 | V6: =FREQUENCY($R$4:$R$40,W5:W25) -> 0 | W6: 379
A7: 4 | B7: 김동주 | C7: 98 | D7: =LOOKUP(C7,#REF!,#REF!) -> #REF! | E7: =((C7-#REF!)/#REF!)*20+100 -> #REF! | F7: 70 | G7: =LOOKUP(F7,#REF!,#REF!) -> #REF! | H7: =((F7-#REF!)/#REF!)*20+100 -> #REF! | I7: 97 | J7: =LOOKUP(I7,#REF!,#REF!) -> #REF! | K7: =((I7-#REF!)/#REF!)*20+100 -> #REF! | L7: =SUM(C7,F7,I7) -> 265 | M7: =SUM(E7,H7,K7) -> #REF! | N7: =RANK(L7,$L$4:$L$40) -> 3 | O7: 38 | P7: 25 | Q7: =(SUM(O7:P7)) -> 63 | R7: =SUM(L7,Q7) -> 328 | S7: =RANK(R7,$R$4:$R$40) -> 3 | U7: 370 | V7: =FREQUENCY($R$4:$R$40,W6:W26) -> 0 | W7: 369
A8: 5 | B8: 김병인 | C8: 95 | D8: =LOOKUP(C8,#REF!,#REF!) -> #REF! | E8: =((C8-#REF!)/#REF!)*20+100 -> #REF! | F8: 58 | G8: =LOOKUP(F8,#REF!,#REF!) -> #REF! | H8: =((F8-#REF!)/#REF!)*20+100 -> #REF! | I8: 71 | J8: =LOOKUP(I8,#REF!,#REF!) -> #REF! | K8: =((I8-#REF!)/#REF!)*20+100 -> #REF! | L8: =SUM(C8,F8,I8) -> 224 | M8: =SUM(E8,H8,K8) -> #REF! | N8: =RANK(L8,$L$4:$L$40) -> 13 | O8: 36 | P8: 35 | Q8: =(SUM(O8:P8)) -> 71 | R8: =SUM(L8,Q8) -> 295 | S8: =RANK(R8,$R$4:$R$40) -> 11 | U8: 360 | V8: =FREQUENCY($R$4:$R$40,W7:W27) -> 2 | W8: 359
A9: 6 | B9: 김송현 | C9: 84 | D9: =LOOKUP(C9,#REF!,#REF!) -> #REF! | E9: =((C9-#REF!)/#REF!)*20+100 -> #REF! | F9: 63 | G9: =LOOKUP(F9,#REF!,#REF!) -> #REF! | H9: =((F9-#REF!)/#REF!)*20+100 -> #REF! | I9: 78 | J9: =LOOKUP(I9,#REF!,#REF!) -> #REF! | K9: =((I9-#REF!)/#REF!)*20+100 -> #REF! | L9: =SUM(C9,F9,I9) -> 225 | M9: =SUM(E9,H9,K9) -> #REF! | N9: =RANK(L9,$L$4:$L$40) -> 12 | O9: 21 | P9: 29 | Q9: =(SUM(O9:P9)) -> 50 | R9: =SUM(L9,Q9) -> 275 | S9: =RANK(R9,$R$4:$R$40) -> 12 | U9: 350 | V9: =FREQUENCY($R$4:$R$40,W8:W28) -> 0 | W9: 349
A10: 7 | B10: 김시온 | C10: 34 | D10: =LOOKUP(C10,#REF!,#REF!) -> #REF! | E10: =((C10-#REF!)/#REF!)*20+100 -> #REF! | F10: 22 | G10: =LOOKUP(F10,#REF!,#REF!) -> #REF! | H10: =((F10-#REF!)/#REF!)*20+100 -> #REF! | I10: 27 | J10: =LOOKUP(I10,#REF!,#REF!) -> #REF! | K10: =((I10-#REF!)/#REF!)*20+100 -> #REF! | L10: =SUM(C10,F10,I10) -> 83 | M10: =SUM(E10,H10,K10) -> #REF! | N10: =RANK(L10,$L$4:$L$40) -> 33 | O10: 17 | P10: 10 | Q10: =(SUM(O10:P10)) -> 27 | R10: =SUM(L10,Q10) -> 110 | S10: =RANK(R10,$R$4:$R$40) -> 33 | U10: 340 | V10: =FREQUENCY($R$4:$R$40,W9:W29) -> 0 | W10: 339
A11: 8 | B11: 김은택 | C11: 94 | D11: =LOOKUP(C11,#REF!,#REF!) -> #REF! | E11: =((C11-#REF!)/#REF!)*20+100 -> #REF! | F11: 62 | G11: =LOOKUP(F11,#REF!,#REF!) -> #REF! | H11: =((F11-#REF!)/#REF!)*20+100 -> #REF! | I11: 92 | J11: =LOOKUP(I11,#REF!,#REF!) -> #REF! | K11: =((I11-#REF!)/#REF!)*20+100 -> #REF! | L11: =SUM(C11,F11,I11) -> 248 | M11: =SUM(E11,H11,K11) -> #REF! | N11: =RANK(L11,$L$4:$L$40) -> 6 | O11: 26 | P11: 25 | Q11: =(SUM(O11:P11)) -> 51 | R11: =SUM(L11,Q11) -> 299 | S11: =RANK(R11,$R$4:$R$40) -> 10 | U11: 330 | V11: =FREQUENCY($R$4:$R$40,W10:W30) -> 0 | W11: 329
A12: 9 | B12: 김종원 | C12: 68 | D12: =LOOKUP(C12,#REF!,#REF!) -> #REF! | E12: =((C12-#REF!)/#REF!)*20+100 -> #REF! | F12: 20 | G12: =LOOKUP(F12,#REF!,#REF!) -> #REF! | H12: =((F12-#REF!)/#REF!)*20+100 -> #REF! | I12: 47 | J12: =LOOKUP(I12,#REF!,#REF!) -> #REF! | K12: =((I12-#REF!)/#REF!)*20+100 -> #REF! | L12: =SUM(C12,F12,I12) -> 135 | M12: =SUM(E12,H12,K12) -> #REF! | N12: =RANK(L12,$L$4:$L$40) -> 27 | O12: 9 | P12: 10 | Q12: =(SUM(O12:P12)) -> 19 | R12: =SUM(L12,Q12) -> 154 | S12: =RANK(R12,$R$4:$R$40) -> 29 | U12: 320 | V12: =FREQUENCY($R$4:$R$40,W11:W31) -> 2 | W12: 319
A13: 10 | B13: 김찬영 | C13: 100 | D13: =LOOKUP(C13,#REF!,#REF!) -> #REF! | E13: =((C13-#REF!)/#REF!)*20+100 -> #REF! | F13: 73 | G13: =LOOKUP(F13,#REF!,#REF!) -> #REF! | H13: =((F13-#REF!)/#REF!)*20+100 -> #REF! | I13: 97 | J13: =LOOKUP(I13,#REF!,#REF!) -> #REF! | K13: =((I13-#REF!)/#REF!)*20+100 -> #REF! | L13: =SUM(C13,F13,I13) -> 270 | M13: =SUM(E13,H13,K13) -> #REF! | N13: =RANK(L13,$L$4:$L$40) -> 2 | O13: 42 | P13: 50 | Q13: =(SUM(O13:P13)) -> 92 | R13: =SUM(L13,Q13) -> 362 | S13: =RANK(R13,$R$4:$R$40) -> 2 | U13: 310 | V13: =FREQUENCY($R$4:$R$40,W12:W32) -> 2 | W13: 309
A14: 11 | B14: 김태원 | C14: 19 | D14: =LOOKUP(C14,#REF!,#REF!) -> #REF! | E14: =((C14-#REF!)/#REF!)*20+100 -> #REF! | F14: 20 | G14: =LOOKUP(F14,#REF!,#REF!) -> #REF! | H14: =((F14-#REF!)/#REF!)*20+100 -> #REF! | I14: 23 | J14: =LOOKUP(I14,#REF!,#REF!) -> #REF! | K14: =((I14-#REF!)/#REF!)*20+100 -> #REF! | L14: =SUM(C14,F14,I14) -> 62 | M14: =SUM(E14,H14,K14) -> #REF! | N14: =RANK(L14,$L$4:$L$40) -> 36 | O14: 15 | P14: 5 | Q14: =(SUM(O14:P14)) -> 20 | R14: =SUM(L14,Q14) -> 82 | S14: =RANK(R14,$R$4:$R$40) -> 36 | U14: 300 | V14: =FREQUENCY($R$4:$R$40,W13:W33) -> 3 | W14: 299
A15: 12 | B15: 박영민 | C15: 94 | D15: =LOOKUP(C15,#REF!,#REF!) -> #REF! | E15: =((C15-#REF!)/#REF!)*20+100 -> #REF! | F15: 48 | G15: =LOOKUP(F15,#REF!,#REF!) -> #REF! | H15: =((F15-#REF!)/#REF!)*20+100 -> #REF! | I15: 47 | J15: =LOOKUP(I15,#REF!,#REF!) -> #REF! | K15: =((I15-#REF!)/#REF!)*20+100 -> #REF! | L15: =SUM(C15,F15,I15) -> 189 | M15: =SUM(E15,H15,K15) -> #REF! | N15: =RANK(L15,$L$4:$L$40) -> 18 | O15: 22 | P15: 23 | Q15: =(SUM(O15:P15)) -> 45 | R15: =SUM(L15,Q15) -> 234 | S15: =RANK(R15,$R$4:$R$40) -> 18 | U15: 290 | V15: =FREQUENCY($R$4:$R$40,W14:W34) -> 2 | W15: 289
A16: 13 | B16: 박찬의 | C16: 96 | D16: =LOOKUP(C16,#REF!,#REF!) -> #REF! | E16: =((C16-#REF!)/#REF!)*20+100 -> #REF! | F16: 53 | G16: =LOOKUP(F16,#REF!,#REF!) -> #REF! | H16: =((F16-#REF!)/#REF!)*20+100 -> #REF! | I16: 77 | J16: =LOOKUP(I16,#REF!,#REF!) -> #REF! | K16: =((I16-#REF!)/#REF!)*20+100 -> #REF! | L16: =SUM(C16,F16,I16) -> 226 | M16: =SUM(E16,H16,K16) -> #REF! | N16: =RANK(L16,$L$4:$L$40) -> 11 | O16: 25 | P16: 24 | Q16: =(SUM(O16:P16)) -> 49 | R16: =SUM(L16,Q16) -> 275 | S16: =RANK(R16,$R$4:$R$40) -> 12 | U16: 280 | V16: =FREQUENCY($R$4:$R$40,W15:W35) -> 0 | W16: 279
A17: 14 | B17: 백종욱 | C17: 90 | D17: =LOOKUP(C17,#REF!,#REF!) -> #REF! | E17: =((C17-#REF!)/#REF!)*20+100 -> #REF! | F17: 51 | G17: =LOOKUP(F17,#REF!,#REF!) -> #REF! | H17: =((F17-#REF!)/#REF!)*20+100 -> #REF! | I17: 22 | J17: =LOOKUP(I17,#REF!,#REF!) -> #REF! | K17: =((I17-#REF!)/#REF!)*20+100 -> #REF! | L17: =SUM(C17,F17,I17) -> 163 | M17: =SUM(E17,H17,K17) -> #REF! | N17: =RANK(L17,$L$4:$L$40) -> 21 | O17: 23 | P17: 13 | Q17: =(SUM(O17:P17)) -> 36 | R17: =SUM(L17,Q17) -> 199 | S17: =RANK(R17,$R$4:$R$40) -> 25 | U17: 270 | V17: =FREQUENCY($R$4:$R$40,W16:W36) -> 3 | W17: 269
A18: 15 | B18: 신윤상 | C18: 97 | D18: =LOOKUP(C18,#REF!,#REF!) -> #REF! | E18: =((C18-#REF!)/#REF!)*20+100 -> #REF! | F18: 59 | G18: =LOOKUP(F18,#REF!,#REF!) -> #REF! | H18: =((F18-#REF!)/#REF!)*20+100 -> #REF! | I18: 87 | J18: =LOOKUP(I18,#REF!,#REF!) -> #REF! | K18: =((I18-#REF!)/#REF!)*20+100 -> #REF! | L18: =SUM(C18,F18,I18) -> 243 | M18: =SUM(E18,H18,K18) -> #REF! | N18: =RANK(L18,$L$4:$L$40) -> 7 | O18: 26 | P18: 38 | Q18: =(SUM(O18:P18)) -> 64 | R18: =SUM(L18,Q18) -> 307 | S18: =RANK(R18,$R$4:$R$40) -> 7 | U18: 260 | V18: =FREQUENCY($R$4:$R$40,W17:W37) -> 0 | W18: 259
A19: 16 | B19: 심관우 | C19: 47 | D19: =LOOKUP(C19,#REF!,#REF!) -> #REF! | E19: =((C19-#REF!)/#REF!)*20+100 -> #REF! | F19: 12 | G19: =LOOKUP(F19,예상등급!$D$19:$D$27,예상등급!$E$19:$E$27) -> 7 | H19: =((F19-예상등급!#REF!)/예상등급!#REF!)*20+100 -> #REF! | I19: 22 | J19: =LOOKUP(I19,#REF!,#REF!) -> #REF! | K19: =((I19-#REF!)/#REF!)*20+100 -> #REF! | L19: =SUM(C19,F19,I19) -> 81 | M19: =SUM(E19,H19,K19) -> #REF! | N19: =RANK(L19,$L$4:$L$40) -> 34 | O19: 14 | P19: 13 | Q19: =(SUM(O19:P19)) -> 27 | R19: =SUM(L19,Q19) -> 108 | S19: =RANK(R19,$R$4:$R$40) -> 34 | U19: 250 | V19: =FREQUENCY($R$4:$R$40,W18:W40) -> 0 | W19: 249
A20: 17 | B20: 엄준혁 | C20: 96 | D20: =LOOKUP(C20,#REF!,#REF!) -> #REF! | E20: =((C20-#REF!)/#REF!)*20+100 -> #REF! | F20: 59 | G20: =LOOKUP(F20,#REF!,#REF!) -> #REF! | H20: =((F20-#REF!)/#REF!)*20+100 -> #REF! | I20: 54 | J20: =LOOKUP(I20,#REF!,#REF!) -> #REF! | K20: =((I20-#REF!)/#REF!)*20+100 -> #REF! | L20: =SUM(C20,F20,I20) -> 209 | M20: =SUM(E20,H20,K20) -> #REF! | N20: =RANK(L20,$L$4:$L$40) -> 15 | O20: 15 | P20: 20 | Q20: =(SUM(O20:P20)) -> 35 | R20: =SUM(L20,Q20) -> 244 | S20: =RANK(R20,$R$4:$R$40) -> 16 | U20: 240 | V20: =FREQUENCY($R$4:$R$40,W19:W40) -> 3 | W20: 239
A21: 18 | B21: 우정찬 | C21: 39 | D21: =LOOKUP(C21,#REF!,#REF!) -> #REF! | E21: =((C21-#REF!)/#REF!)*20+100 -> #REF! | F21: 16 | G21: =LOOKUP(F21,#REF!,#REF!) -> #REF! | H21: =((F21-#REF!)/#REF!)*20+100 -> #REF! | I21: 47 | J21: =LOOKUP(I21,#REF!,#REF!) -> #REF! | K21: =((I21-#REF!)/#REF!)*20+100 -> #REF! | L21: =SUM(C21,F21,I21) -> 102 | M21: =SUM(E21,H21,K21) -> #REF! | N21: =RANK(L21,$L$4:$L$40) -> 30 | O21: 13 | P21: 17 | Q21: =(SUM(O21:P21)) -> 30 | R21: =SUM(L21,Q21) -> 132 | S21: =RANK(R21,$R$4:$R$40) -> 31 | U21: 230 | V21: =FREQUENCY($R$4:$R$40,W20:W40) -> 1 | W21: 229
A22: 19 | B22: 유기환 | C22: 53 | D22: =LOOKUP(C22,#REF!,#REF!) -> #REF! | E22: =((C22-#REF!)/#REF!)*20+100 -> #REF! | F22: 7 | G22: =LOOKUP(F22,#REF!,#REF!) -> #REF! | H22: =((F22-#REF!)/#REF!)*20+100 -> #REF! | I22: 42 | J22: =LOOKUP(I22,#REF!,#REF!) -> #REF! | K22: =((I22-#REF!)/#REF!)*20+100 -> #REF! | L22: =SUM(C22,F22,I22) -> 102 | M22: =SUM(E22,H22,K22) -> #REF! | N22: =RANK(L22,$L$4:$L$40) -> 30 | O22: 21 | P22: 16 | Q22: =(SUM(O22:P22)) -> 37 | R22: =SUM(L22,Q22) -> 139 | S22: =RANK(R22,$R$4:$R$40) -> 30 | U22: 220 | V22: =FREQUENCY($R$4:$R$40,W21:W41) -> 2 | W22: 219
A23: 20 | B23: 유남희 | C23: 35 | D23: =LOOKUP(C23,#REF!,#REF!) -> #REF! | E23: =((C23-#REF!)/#REF!)*20+100 -> #REF! | F23: 31 | G23: =LOOKUP(F23,#REF!,#REF!) -> #REF! | H23: =((F23-#REF!)/#REF!)*20+100 -> #REF! | I23: 32 | J23: =LOOKUP(I23,#REF!,#REF!) -> #REF! | K23: =((I23-#REF!)/#REF!)*20+100 -> #REF! | L23: =SUM(C23,F23,I23) -> 98 | M23: =SUM(E23,H23,K23) -> #REF! | N23: =RANK(L23,$L$4:$L$40) -> 32 | O23: 6 | P23: 16 | Q23: =(SUM(O23:P23)) -> 22 | R23: =SUM(L23,Q23) -> 120 | S23: =RANK(R23,$R$4:$R$40) -> 32 | U23: 210 | V23: =FREQUENCY($R$4:$R$40,W22:W42) -> 0 | W23: 209
A24: 21 | B24: 유승민 | C24: 77 | D24: =LOOKUP(C24,#REF!,#REF!) -> #REF! | E24: =((C24-#REF!)/#REF!)*20+100 -> #REF! | F24: 39 | G24: =LOOKUP(F24,#REF!,#REF!) -> #REF! | H24: =((F24-#REF!)/#REF!)*20+100 -> #REF! | I24: 41 | J24: =LOOKUP(I24,#REF!,#REF!) -> #REF! | K24: =((I24-#REF!)/#REF!)*20+100 -> #REF! | L24: =SUM(C24,F24,I24) -> 157 | M24: =SUM(E24,H24,K24) -> #REF! | N24: =RANK(L24,$L$4:$L$40) -> 22 | O24: 16 | P24: 21 | Q24: =(SUM(O24:P24)) -> 37 | R24: =SUM(L24,Q24) -> 194 | S24: =RANK(R24,$R$4:$R$40) -> 27 | U24: 200 | V24: =FREQUENCY($R$4:$R$40,W23:W43) -> 4 | W24: 199
A25: 22 | B25: 유재상 | C25: 19 | D25: =LOOKUP(C25,#REF!,#REF!) -> #REF! | E25: =((C25-#REF!)/#REF!)*20+100 -> #REF! | F25: 15 | G25: =LOOKUP(F25,#REF!,#REF!) -> #REF! | H25: =((F25-#REF!)/#REF!)*20+100 -> #REF! | I25: 28 | J25: =LOOKUP(I25,#REF!,#REF!) -> #REF! | K25: =((I25-#REF!)/#REF!)*20+100 -> #REF! | L25: =SUM(C25,F25,I25) -> 62 | M25: =SUM(E25,H25,K25) -> #REF! | N25: =RANK(L25,$L$4:$L$40) -> 36 | O25: 9 | Q25: =(SUM(O25:P25)) -> 9 | R25: =SUM(L25,Q25) -> 71 | S25: =RANK(R25,$R$4:$R$40) -> 37 | U25: 190 | V25: =FREQUENCY($R$4:$R$40,W24:W44) -> 3 | W25: 189
A26: 23 | B26: 유현승 | C26: 100 | D26: =LOOKUP(C26,#REF!,#REF!) -> #REF! | E26: =((C26-#REF!)/#REF!)*20+100 -> #REF! | F26: 58 | G26: =LOOKUP(F26,#REF!,#REF!) -> #REF! | H26: =((F26-#REF!)/#REF!)*20+100 -> #REF! | I26: 78 | J26: =LOOKUP(I26,#REF!,#REF!) -> #REF! | K26: =((I26-#REF!)/#REF!)*20+100 -> #REF! | L26: =SUM(C26,F26,I26) -> 236 | M26: =SUM(E26,H26,K26) -> #REF! | N26: =RANK(L26,$L$4:$L$40) -> 9 | O26: 50 | P26: 27 | Q26: =(SUM(O26:P26)) -> 77 | R26: =SUM(L26,Q26) -> 313 | S26: =RANK(R26,$R$4:$R$40) -> 6 | U26: 190이하 | V26: =FREQUENCY($R$4:$R$40,W25:W45) -> 10
A27: 24 | B27: 이준환 | C27: 79 | D27: =LOOKUP(C27,#REF!,#REF!) -> #REF! | E27: =((C27-#REF!)/#REF!)*20+100 -> #REF! | F27: 45 | G27: =LOOKUP(F27,#REF!,#REF!) -> #REF! | H27: =((F27-#REF!)/#REF!)*20+100 -> #REF! | I27: 66 | J27: =LOOKUP(I27,#REF!,#REF!) -> #REF! | K27: =((I27-#REF!)/#REF!)*20+100 -> #REF! | L27: =SUM(C27,F27,I27) -> 190 | M27: =SUM(E27,H27,K27) -> #REF! | N27: =RANK(L27,$L$4:$L$40) -> 17 | O27: 16 | Q27: =(SUM(O27:P27)) -> 16 | R27: =SUM(L27,Q27) -> 206 | S27: =RANK(R27,$R$4:$R$40) -> 21 | U27: 합계 | V27: =SUM(V4:V26) -> 37
A28: 25 | B28: 이지석 | C28: 74 | D28: =LOOKUP(C28,#REF!,#REF!) -> #REF! | E28: =((C28-#REF!)/#REF!)*20+100 -> #REF! | F28: 28 | G28: =LOOKUP(F28,#REF!,#REF!) -> #REF! | H28: =((F28-#REF!)/#REF!)*20+100 -> #REF! | I28: 48 | J28: =LOOKUP(I28,#REF!,#REF!) -> #REF! | K28: =((I28-#REF!)/#REF!)*20+100 -> #REF! | L28: =SUM(C28,F28,I28) -> 150 | M28: =SUM(E28,H28,K28) -> #REF! | N28: =RANK(L28,$L$4:$L$40) -> 24 | O28: 28 | P28: 27 | Q28: =(SUM(O28:P28)) -> 55 | R28: =SUM(L28,Q28) -> 205 | S28: =RANK(R28,$R$4:$R$40) -> 22
A29: 26 | B29: 이창윤 | C29: 18 | D29: =LOOKUP(C29,#REF!,#REF!) -> #REF! | E29: =((C29-#REF!)/#REF!)*20+100 -> #REF! | F29: 77 | G29: =LOOKUP(F29,#REF!,#REF!) -> #REF! | H29: =((F29-#REF!)/#REF!)*20+100 -> #REF! | I29: 28 | J29: =LOOKUP(I29,#REF!,#REF!) -> #REF! | K29: =((I29-#REF!)/#REF!)*20+100 -> #REF! | L29: =SUM(C29,F29,I29) -> 123 | M29: =SUM(E29,H29,K29) -> #REF! | N29: =RANK(L29,$L$4:$L$40) -> 29 | O29: 36 | P29: 41 | Q29: =(SUM(O29:P29)) -> 77 | R29: =SUM(L29,Q29) -> 200 | S29: =RANK(R29,$R$4:$R$40) -> 24
A30: 27 | B30: 이하민 | C30: 93 | D30: =LOOKUP(C30,#REF!,#REF!) -> #REF! | E30: =((C30-#REF!)/#REF!)*20+100 -> #REF! | F30: 32 | G30: =LOOKUP(F30,#REF!,#REF!) -> #REF! | H30: =((F30-#REF!)/#REF!)*20+100 -> #REF! | I30: 9 | J30: =LOOKUP(I30,#REF!,#REF!) -> #REF! | K30: =((I30-#REF!)/#REF!)*20+100 -> #REF! | L30: =SUM(C30,F30,I30) -> 134 | M30: =SUM(E30,H30,K30) -> #REF! | N30: =RANK(L30,$L$4:$L$40) -> 28 | O30: 21 | P30: 40 | Q30: =(SUM(O30:P30)) -> 61 | R30: =SUM(L30,Q30) -> 195 | S30: =RANK(R30,$R$4:$R$40) -> 26 | U30: 최고점
A31: 28 | B31: 임준영 | C31: 83 | D31: =LOOKUP(C31,#REF!,#REF!) -> #REF! | E31: =((C31-#REF!)/#REF!)*20+100 -> #REF! | F31: 54 | G31: =LOOKUP(F31,#REF!,#REF!) -> #REF! | H31: =((F31-#REF!)/#REF!)*20+100 -> #REF! | I31: 81 | J31: =LOOKUP(I31,#REF!,#REF!) -> #REF! | K31: =((I31-#REF!)/#REF!)*20+100 -> #REF! | L31: =SUM(C31,F31,I31) -> 218 | M31: =SUM(E31,H31,K31) -> #REF! | N31: =RANK(L31,$L$4:$L$40) -> 14 | O31: 36 | P31: 20 | Q31: =(SUM(O31:P31)) -> 56 | R31: =SUM(L31,Q31) -> 274 | S31: =RANK(R31,$R$4:$R$40) -> 14 | U31: =MAX(R4:R40) -> 369
A32: 29 | B32: 정관수 | C32: 27 | D32: =LOOKUP(C32,#REF!,#REF!) -> #REF! | E32: =((C32-#REF!)/#REF!)*20+100 -> #REF! | F32: 30 | G32: =LOOKUP(F32,#REF!,#REF!) -> #REF! | H32: =((F32-#REF!)/#REF!)*20+100 -> #REF! | I32: 20 | J32: =LOOKUP(I32,#REF!,#REF!) -> #REF! | K32: =((I32-#REF!)/#REF!)*20+100 -> #REF! | L32: =SUM(C32,F32,I32) -> 77 | M32: =SUM(E32,H32,K32) -> #REF! | N32: =RANK(L32,$L$4:$L$40) -> 35 | O32: 7 | P32: 15 | Q32: =(SUM(O32:P32)) -> 22 | R32: =SUM(L32,Q32) -> 99 | S32: =RANK(R32,$R$4:$R$40) -> 35
A33: 30 | B33: 정동륜 | C33: 100 | D33: =LOOKUP(C33,#REF!,#REF!) -> #REF! | E33: =((C33-#REF!)/#REF!)*20+100 -> #REF! | F33: 96 | G33: =LOOKUP(F33,#REF!,#REF!) -> #REF! | H33: =((F33-#REF!)/#REF!)*20+100 -> #REF! | I33: 87 | J33: =LOOKUP(I33,#REF!,#REF!) -> #REF! | K33: =((I33-#REF!)/#REF!)*20+100 -> #REF! | L33: =SUM(C33,F33,I33) -> 283 | M33: =SUM(E33,H33,K33) -> #REF! | N33: =RANK(L33,$L$4:$L$40) -> 1 | O33: 42 | P33: 44 | Q33: =(SUM(O33:P33)) -> 86 | R33: =SUM(L33,Q33) -> 369 | S33: =RANK(R33,$R$4:$R$40) -> 1 | U33: 최하점
A34: 31 | B34: 조정열 | C34: 85 | D34: =LOOKUP(C34,#REF!,#REF!) -> #REF! | E34: =((C34-#REF!)/#REF!)*20+100 -> #REF! | F34: 43 | G34: =LOOKUP(F34,#REF!,#REF!) -> #REF! | H34: =((F34-#REF!)/#REF!)*20+100 -> #REF! | I34: 43 | J34: =LOOKUP(I34,#REF!,#REF!) -> #REF! | K34: =((I34-#REF!)/#REF!)*20+100 -> #REF! | L34: =SUM(C34,F34,I34) -> 171 | M34: =SUM(E34,H34,K34) -> #REF! | N34: =RANK(L34,$L$4:$L$40) -> 20 | O34: 16 | P34: 36 | Q34: =(SUM(O34:P34)) -> 52 | R34: =SUM(L34,Q34) -> 223 | S34: =RANK(R34,$R$4:$R$40) -> 20 | U34: =MIN(R4:R40) -> 71
A35: 32 | B35: 조화평 | C35: 71 | D35: =LOOKUP(C35,#REF!,#REF!) -> #REF! | E35: =((C35-#REF!)/#REF!)*20+100 -> #REF! | F35: 54 | G35: =LOOKUP(F35,#REF!,#REF!) -> #REF! | H35: =((F35-#REF!)/#REF!)*20+100 -> #REF! | I35: 64 | J35: =LOOKUP(I35,#REF!,#REF!) -> #REF! | K35: =((I35-#REF!)/#REF!)*20+100 -> #REF! | L35: =SUM(C35,F35,I35) -> 189 | M35: =SUM(E35,H35,K35) -> #REF! | N35: =RANK(L35,$L$4:$L$40) -> 18 | O35: 20 | P35: 33 | Q35: =(SUM(O35:P35)) -> 53 | R35: =SUM(L35,Q35) -> 242 | S35: =RANK(R35,$R$4:$R$40) -> 17
